Workbook
Name Subassembly: 'Top Assy'!$A$91:$I$103
Name Year: 'Top Assy'!$B$9

Sheet Top Assy
A2: CUSTOMER:
A3: P/N: | D3: NSN #: | F3: Yield %: | G3: 0.95
A4: REV: | D4: SOL #:
A5: QUOTE LOG No.: | D5: RFQ #: | F5: Comments:
A6: QTY: | B6: =F13&", "&G13&", "&H13&", "&I13&", "&J13&", "&K13&", "&L13&", "&M13 -> 10, 25, 50, 75, 100, 250, 500, 1000
A7: DATE:
A8: ESTIMATOR:
A9: Labor Rate Year: | B9: 2026
A11: MANUFACTURING OPERATIONS | F11: COST ESTIMATED QUANTITIES | N11: NRE/SET-UP
B13: SET-UP TIME | C13: RUN TIME | E13: LABOR RATE | F13: 10 | G13: 25 | H13: 50 | I13: 75 | J13: 100 | K13: 250 | L13: 500 | M13: 1000 | N13: 1
A14: Program | E14: 0 | N14: =(($B14/N$13*$E14)+($C14*$E14)) -> 0
A15: Fixtures | E15: 0 | N15: =(($B15/N$13*$E15)+($C15*$E15)) -> 0
A16: Mill/Turn | E16: 0 | F16: =(($B16/F$13*$E16)+($C16*$E16)) -> 0 | G16: =(($B16/G$13*$E16)+($C16*$E16)) -> 0 | H16: =(($B16/H$13*$E16)+($C16*$E16)) -> 0 | I16: =(($B16/I$13*$E16)+($C16*$E16)) -> 0 | J16: =(($B16/J$13*$E16)+($C16*$E16)) -> 0 | K16: =(($B16/K$13*$E16)+($C16*$E16)) -> 0 | L16: =(($B16/L$13*$E16)+($C16*$E16)) -> 0 | M16: =(($B16/M$13*$E16)+($C16*$E16)) -> 0
A17: Metals - Mills | E17: 0 | F17: =(($B17/F$13*$E17)+($C17*$E17)) -> 0 | G17: =(($B17/G$13*$E17)+($C17*$E17)) -> 0 | H17: =(($B17/H$13*$E17)+($C17*$E17)) -> 0 | I17: =(($B17/I$13*$E17)+($C17*$E17)) -> 0 | J17: =(($B17/J$13*$E17)+($C17*$E17)) -> 0 | K17: =(($B17/K$13*$E17)+($C17*$E17)) -> 0 | L17: =(($B17/L$13*$E17)+($C17*$E17)) -> 0 | M17: =(($B17/M$13*$E17)+($C17*$E17)) -> 0
A18: Metals - Lathe | E18: 0 | F18: =(($B18/F$13*$E18)+($C18*$E18)) -> 0 | G18: =(($B18/G$13*$E18)+($C18*$E18)) -> 0 | H18: =(($B18/H$13*$E18)+($C18*$E18)) -> 0 | I18: =(($B18/I$13*$E18)+($C18*$E18)) -> 0 | J18: =(($B18/J$13*$E18)+($C18*$E18)) -> 0 | K18: =(($B18/K$13*$E18)+($C18*$E18)) -> 0 | L18: =(($B18/L$13*$E18)+($C18*$E18)) -> 0 | M18: =(($B18/M$13*$E18)+($C18*$E18)) -> 0
A19: Rubber Mold | E19: 0 | F19: =(($B19/F$13*$E19)+($C19*$E19)) -> 0 | G19: =(($B19/G$13*$E19)+($C19*$E19)) -> 0 | H19: =(($B19/H$13*$E19)+($C19*$E19)) -> 0 | I19: =(($B19/I$13*$E19)+($C19*$E19)) -> 0 | J19: =(($B19/J$13*$E19)+($C19*$E19)) -> 0 | K19: =(($B19/K$13*$E19)+($C19*$E19)) -> 0 | L19: =(($B19/L$13*$E19)+($C19*$E19)) -> 0 | M19: =(($B19/M$13*$E19)+($C19*$E19)) -> 0
A20: Plastic Injection Mold | E20: 0 | F20: =(($B20/F$13*$E20)+($C20*$E20)) -> 0 | G20: =(($B20/G$13*$E20)+($C20*$E20)) -> 0 | H20: =(($B20/H$13*$E20)+($C20*$E20)) -> 0 | I20: =(($B20/I$13*$E20)+($C20*$E20)) -> 0 | J20: =(($B20/J$13*$E20)+($C20*$E20)) -> 0 | K20: =(($B20/K$13*$E20)+($C20*$E20)) -> 0 | L20: =(($B20/L$13*$E20)+($C20*$E20)) -> 0 | M20: =(($B20/M$13*$E20)+($C20*$E20)) -> 0
A21: Plastic Compression Mold | E21: 0 | F21: =(($B21/F$13*$E21)+($C21*$E21)) -> 0 | G21: =(($B21/G$13*$E21)+($C21*$E21)) -> 0 | H21: =(($B21/H$13*$E21)+($C21*$E21)) -> 0 | I21: =(($B21/I$13*$E21)+($C21*$E21)) -> 0 | J21: =(($B21/J$13*$E21)+($C21*$E21)) -> 0 | K21: =(($B21/K$13*$E21)+($C21*$E21)) -> 0 | L21: =(($B21/L$13*$E21)+($C21*$E21)) -> 0 | M21: =(($B21/M$13*$E21)+($C21*$E21)) -> 0
A22: Waterjet - Operator | E22: 0 | F22: =(($B22/F$13*$E22)+($C22*$E22)) -> 0 | G22: =(($B22/G$13*$E22)+($C22*$E22)) -> 0 | H22: =(($B22/H$13*$E22)+($C22*$E22)) -> 0 | I22: =(($B22/I$13*$E22)+($C22*$E22)) -> 0 | J22: =(($B22/J$13*$E22)+($C22*$E22)) -> 0 | K22: =(($B22/K$13*$E22)+($C22*$E22)) -> 0 | L22: =(($B22/L$13*$E22)+($C22*$E22)) -> 0 | M22: =(($B22/M$13*$E22)+($C22*$E22)) -> 0
A23: Assembly, Die Punch, Deburr | E23: 0 | F23: =(($B23/F$13*$E23)+($C23*$E23)) -> 0 | G23: =(($B23/G$13*$E23)+($C23*$E23)) -> 0 | H23: =(($B23/H$13*$E23)+($C23*$E23)) -> 0 | I23: =(($B23/I$13*$E23)+($C23*$E23)) -> 0 | J23: =(($B23/J$13*$E23)+($C23*$E23)) -> 0 | K23: =(($B23/K$13*$E23)+($C23*$E23)) -> 0 | L23: =(($B23/L$13*$E23)+($C23*$E23)) -> 0 | M23: =(($B23/M$13*$E23)+($C23*$E23)) -> 0
A24: Quality Inspection | E24: 0 | F24: =(($B24/F$13*$E24)+($C24*$E24)) -> 0 | G24: =(($B24/G$13*$E24)+($C24*$E24)) -> 0 | H24: =(($B24/H$13*$E24)+($C24*$E24)) -> 0 | I24: =(($B24/I$13*$E24)+($C24*$E24)) -> 0 | J24: =(($B24/J$13*$E24)+($C24*$E24)) -> 0 | K24: =(($B24/K$13*$E24)+($C24*$E24)) -> 0 | L24: =(($B24/L$13*$E24)+($C24*$E24)) -> 0 | M24: =(($B24/M$13*$E24)+($C24*$E24)) -> 0
A25: ID & Pack | E25: 0 | F25: =(($B25/F$13*$E25)+($C25*$E25)) -> 0 | G25: =(($B25/G$13*$E25)+($C25*$E25)) -> 0 | H25: =(($B25/H$13*$E25)+($C25*$E25)) -> 0 | I25: =(($B25/I$13*$E25)+($C25*$E25)) -> 0 | J25: =(($B25/J$13*$E25)+($C25*$E25)) -> 0 | K25: =(($B25/K$13*$E25)+($C25*$E25)) -> 0 | L25: =(($B25/L$13*$E25)+($C25*$E25)) -> 0 | M25: =(($B25/M$13*$E25)+($C25*$E25)) -> 0
C26: Labor | E26: Basic LABOR | F26: =SUM(F16:F25) -> 0 | G26: =SUM(G16:G25) -> 0 | H26: =SUM(H16:H25) -> 0 | I26: =SUM(I16:I25) -> 0 | J26: =SUM(J16:J25) -> 0 | K26: =SUM(K16:K25) -> 0 | L26: =SUM(L16:L25) -> 0 | M26: =SUM(M16:M25) -> 0 | N26: =SUM(N14:N25) -> 0
B27: T. setup | C27: T.RUN | E27: hrs | F27: =(($B$28/F13)+$C$28)/60 -> 0 | G27: =(($B$28/G13)+$C$28)/60 -> 0 | H27: =(($B$28/H13)+$C$28)/60 -> 0 | I27: =(($B$28/I13)+$C$28)/60 -> 0 | J27: =(($B$28/J13)+$C$28)/60 -> 0 | K27: =(($B$28/K13)+$C$28)/60 -> 0 | L27: =(($B$28/L13)+$C$28)/60 -> 0 | M27: =(($B$28/M13)+$C$28)/60 -> 0
B28: =SUM(B16:B25) -> 0 | C28: =SUM(C16:C25) -> 0 | D28: 0 | E28: BURDEN | F28: =F26*$D$28 -> 0 | G28: =G26*$D$28 -> 0 | H28: =H26*$D$28 -> 0 | I28: =I26*$D$28 -> 0 | J28: =J26*$D$28 -> 0 | K28: =K26*$D$28 -> 0 | L28: =L26*$D$28 -> 0 | M28: =M26*$D$28 -> 0
E30: Total | F30: =F26+F28 -> 0 | G30: =G26+G28 -> 0 | H30: =H26+H28 -> 0 | I30: =I26+I28 -> 0 | J30: =J26+J28 -> 0 | K30: =K26+K28 -> 0 | L30: =L26+L28 -> 0 | M30: =M26+M28 -> 0 | N30: =N26 -> 0
A32: Raw Materials & Hardware | B32: Matl UoM | C32: Parts QTY | D32: Unit Price | E32: Matl Burden | F32: ="Qty: "& F13 -> Qty: 10 | G32: ="Qty: "& G13 -> Qty: 25 | H32: ="Qty: "& H13 -> Qty: 50 | I32: ="Qty: "& I13 -> Qty: 75 | J32: ="Qty: "& J13 -> Qty: 100 | K32: ="Qty: "& K13 -> Qty: 250 | L32: ="Qty: "& L13 -> Qty: 500 | M32: ="Qty: "& M13 -> Qty: 1000 | N32: Amortize/ Min Buy
E33: =C33*D33 -> 0 | F33: =IF($N33=TRUE,$E33/F$13,$E33*(1+(1/F$13))) -> 0 | G33: =IF($N33=TRUE,$E33/G$13,$E33*(1+(1/G$13))) -> 0 | H33: =IF($N33=TRUE,$E33/H$13,$E33*(1+(1/H$13))) -> 0 | I33: =IF($N33=TRUE,$E33/I$13,$E33*(1+(1/I$13))) -> 0 | J33: =IF($N33=TRUE,$E33/J$13,$E33*(1+(1/J$13))) -> 0 | K33: =IF($N33=TRUE,$E33/K$13,$E33*(1+(1/K$13))) -> 0 | L33: =IF($N33=TRUE,E33/L$13,$E33*(1+(1/L$13))) -> 0 | M33: =IF($N33=TRUE,E33/M$13,$E33*(1+(1/M$13))) -> 0 | N33: FALSE
E34: =C34*D34 -> 0 | F34: =IF($N34=TRUE,$E34/F$13,$E34*(1+(1/F$13))) -> 0 | G34: =IF($N34=TRUE,$E34/G$13,$E34*(1+(1/G$13))) -> 0 | H34: =IF($N34=TRUE,$E34/H$13,$E34*(1+(1/H$13))) -> 0 | I34: =IF($N34=TRUE,$E34/I$13,$E34*(1+(1/I$13))) -> 0 | J34: =IF($N34=TRUE,$E34/J$13,$E34*(1+(1/J$13))) -> 0 | K34: =IF($N34=TRUE,$E34/K$13,$E34*(1+(1/K$13))) -> 0 | L34: =IF($N34=TRUE,E34/L$13,$E34*(1+(1/L$13))) -> 0 | M34: =IF($N34=TRUE,E34/M$13,$E34*(1+(1/M$13))) -> 0 | N34: FALSE
E35: =C35*D35 -> 0 | F35: =IF($N35=TRUE,$E35/F$13,$E35*(1+(1/F$13))) -> 0 | G35: =IF($N35=TRUE,$E35/G$13,$E35*(1+(1/G$13))) -> 0 | H35: =IF($N35=TRUE,$E35/H$13,$E35*(1+(1/H$13))) -> 0 | I35: =IF($N35=TRUE,$E35/I$13,$E35*(1+(1/I$13))) -> 0 | J35: =IF($N35=TRUE,$E35/J$13,$E35*(1+(1/J$13))) -> 0 | K35: =IF($N35=TRUE,$E35/K$13,$E35*(1+(1/K$13))) -> 0 | L35: =IF($N35=TRUE,E35/L$13,$E35*(1+(1/L$13))) -> 0 | M35: =IF($N35=TRUE,E35/M$13,$E35*(1+(1/M$13))) -> 0 | N35: FALSE | S35: QTY | T35: Total
E36: =C36*D36 -> 0 | F36: =IF($N36=TRUE,$E36/F$13,$E36*(1+(1/F$13))) -> 0 | G36: =IF($N36=TRUE,$E36/G$13,$E36*(1+(1/G$13))) -> 0 | H36: =IF($N36=TRUE,$E36/H$13,$E36*(1+(1/H$13))) -> 0 | I36: =IF($N36=TRUE,$E36/I$13,$E36*(1+(1/I$13))) -> 0 | J36: =IF($N36=TRUE,$E36/J$13,$E36*(1+(1/J$13))) -> 0 | K36: =IF($N36=TRUE,$E36/K$13,$E36*(1+(1/K$13))) -> 0 | L36: =IF($N36=TRUE,E36/L$13,$E36*(1+(1/L$13))) -> 0 | M36: =IF($N36=TRUE,E36/M$13,$E36*(1+(1/M$13))) -> 0 | N36: FALSE | S36: =M13 -> 1000 | T36: =M80 -> 0
E37: =C37*D37 -> 0 | F37: =IF($N37=TRUE,$E37/F$13,$E37*(1+(1/F$13))) -> 0 | G37: =IF($N37=TRUE,$E37/G$13,$E37*(1+(1/G$13))) -> 0 | H37: =IF($N37=TRUE,$E37/H$13,$E37*(1+(1/H$13))) -> 0 | I37: =IF($N37=TRUE,$E37/I$13,$E37*(1+(1/I$13))) -> 0 | J37: =IF($N37=TRUE,$E37/J$13,$E37*(1+(1/J$13))) -> 0 | K37: =IF($N37=TRUE,$E37/K$13,$E37*(1+(1/K$13))) -> 0 | L37: =IF($N37=TRUE,E37/L$13,$E37*(1+(1/L$13))) -> 0 | M37: =IF($N37=TRUE,E37/M$13,$E37*(1+(1/M$13))) -> 0 | N37: FALSE | S37: =L13 -> 500 | T37: =L80 -> 0
E38: =C38*D38 -> 0 | F38: =IF($N38=TRUE,$E38/F$13,$E38*(1+(1/F$13))) -> 0 | G38: =IF($N38=TRUE,$E38/G$13,$E38*(1+(1/G$13))) -> 0 | H38: =IF($N38=TRUE,$E38/H$13,$E38*(1+(1/H$13))) -> 0 | I38: =IF($N38=TRUE,$E38/I$13,$E38*(1+(1/I$13))) -> 0 | J38: =IF($N38=TRUE,$E38/J$13,$E38*(1+(1/J$13))) -> 0 | K38: =IF($N38=TRUE,$E38/K$13,$E38*(1+(1/K$13))) -> 0 | L38: =IF($N38=TRUE,E38/L$13,$E38*(1+(1/L$13))) -> 0 | M38: =IF($N38=TRUE,E38/M$13,$E38*(1+(1/M$13))) -> 0 | N38: FALSE | S38: =I13 -> 75 | T38: =I80 -> 0
E39: =C39*D39 -> 0 | F39: =IF($N39=TRUE,$E39/F$13,$E39*(1+(1/F$13))) -> 0 | G39: =IF($N39=TRUE,$E39/G$13,$E39*(1+(1/G$13))) -> 0 | H39: =IF($N39=TRUE,$E39/H$13,$E39*(1+(1/H$13))) -> 0 | I39: =IF($N39=TRUE,$E39/I$13,$E39*(1+(1/I$13))) -> 0 | J39: =IF($N39=TRUE,$E39/J$13,$E39*(1+(1/J$13))) -> 0 | K39: =IF($N39=TRUE,$E39/K$13,$E39*(1+(1/K$13))) -> 0 | L39: =IF($N39=TRUE,E39/L$13,$E39*(1+(1/L$13))) -> 0 | M39: =IF($N39=TRUE,E39/M$13,$E39*(1+(1/M$13))) -> 0 | N39: FALSE | S39: =H13 -> 50 | T39: =H80 -> 0
E40: =C40*D40 -> 0 | F40: =IF($N40=TRUE,$E40/F$13,$E40*(1+(1/F$13))) -> 0 | G40: =IF($N40=TRUE,$E40/G$13,$E40*(1+(1/G$13))) -> 0 | H40: =IF($N40=TRUE,$E40/H$13,$E40*(1+(1/H$13))) -> 0 | I40: =IF($N40=TRUE,$E40/I$13,$E40*(1+(1/I$13))) -> 0 | J40: =IF($N40=TRUE,$E40/J$13,$E40*(1+(1/J$13))) -> 0 | K40: =IF($N40=TRUE,$E40/K$13,$E40*(1+(1/K$13))) -> 0 | L40: =IF($N40=TRUE,E40/L$13,$E40*(1+(1/L$13))) -> 0 | M40: =IF($N40=TRUE,E40/M$13,$E40*(1+(1/M$13))) -> 0 | N40: FALSE | S40: =G13 -> 25 | T40: =G80 -> 0
E41: =C41*D41 -> 0 | F41: =IF($N41=TRUE,$E41/F$13,$E41*(1+(1/F$13))) -> 0 | G41: =IF($N41=TRUE,$E41/G$13,$E41*(1+(1/G$13))) -> 0 | H41: =IF($N41=TRUE,$E41/H$13,$E41*(1+(1/H$13))) -> 0 | I41: =IF($N41=TRUE,$E41/I$13,$E41*(1+(1/I$13))) -> 0 | J41: =IF($N41=TRUE,$E41/J$13,$E41*(1+(1/J$13))) -> 0 | K41: =IF($N41=TRUE,$E41/K$13,$E41*(1+(1/K$13))) -> 0 | L41: =IF($N41=TRUE,E41/L$13,$E41*(1+(1/L$13))) -> 0 | M41: =IF($N41=TRUE,E41/M$13,$E41*(1+(1/M$13))) -> 0 | N41: FALSE | S41: =F13 -> 10 | T41: =F80 -> 0
E42: =C42*D42 -> 0 | F42: =IF($N42=TRUE,$E42/F$13,$E42*(1+(1/F$13))) -> 0 | G42: =IF($N42=TRUE,$E42/G$13,$E42*(1+(1/G$13))) -> 0 | H42: =IF($N42=TRUE,$E42/H$13,$E42*(1+(1/H$13))) -> 0 | I42: =IF($N42=TRUE,$E42/I$13,$E42*(1+(1/I$13))) -> 0 | J42: =IF($N42=TRUE,$E42/J$13,$E42*(1+(1/J$13))) -> 0 | K42: =IF($N42=TRUE,$E42/K$13,$E42*(1+(1/K$13))) -> 0 | L42: =IF($N42=TRUE,E42/L$13,$E42*(1+(1/L$13))) -> 0 | M42: =IF($N42=TRUE,E42/M$13,$E42*(1+(1/M$13))) -> 0 | N42: FALSE
E43: =C43*D43 -> 0 | F43: =IF($N43=TRUE,$E43/F$13,$E43*(1+(1/F$13))) -> 0 | G43: =IF($N43=TRUE,$E43/G$13,$E43*(1+(1/G$13))) -> 0 | H43: =IF($N43=TRUE,$E43/H$13,$E43*(1+(1/H$13))) -> 0 | I43: =IF($N43=TRUE,$E43/I$13,$E43*(1+(1/I$13))) -> 0 | J43: =IF($N43=TRUE,$E43/J$13,$E43*(1+(1/J$13))) -> 0 | K43: =IF($N43=TRUE,$E43/K$13,$E43*(1+(1/K$13))) -> 0 | L43: =IF($N43=TRUE,E43/L$13,$E43*(1+(1/L$13))) -> 0 | M43: =IF($N43=TRUE,E43/M$13,$E43*(1+(1/M$13))) -> 0 | N43: FALSE
E44: =C44*D44 -> 0 | F44: =IF($N44=TRUE,$E44/F$13,$E44*(1+(1/F$13))) -> 0 | G44: =IF($N44=TRUE,$E44/G$13,$E44*(1+(1/G$13))) -> 0 | H44: =IF($N44=TRUE,$E44/H$13,$E44*(1+(1/H$13))) -> 0 | I44: =IF($N44=TRUE,$E44/I$13,$E44*(1+(1/I$13))) -> 0 | J44: =IF($N44=TRUE,$E44/J$13,$E44*(1+(1/J$13))) -> 0 | K44: =IF($N44=TRUE,$E44/K$13,$E44*(1+(1/K$13))) -> 0 | L44: =IF($N44=TRUE,E44/L$13,$E44*(1+(1/L$13))) -> 0 | M44: =IF($N44=TRUE,E44/M$13,$E44*(1+(1/M$13))) -> 0 | N44: FALSE
A45: Processes | B45: QTY | C45: Subassy? | D45: SETUP $ | E45: RUN$ EA.
...

Sheet Subassy 1
A2: CUSTOMER: | F2: Comments:
A3: P/N: | B3: 1 | D3: NSN #:
A4: REV: | D4: SOL #:
A5: QUOTE LOG No.: | D5: RFQ #:
A6: QTY: | B6: =F13&", "&G13&", "&H13&", "&I13&", "&J13&", "&K13&", "&L13&", "&M13 -> 10, 25, 50, 75, 100, 250, 500, 1000
A7: DATE:
A8: ESTIMATOR:
A11: MANUFACTURING OPERATIONS | F11: COST ESTIMATED QUANTITIES | N11: NRE/SET-UP
B13: SET-UP TIME | C13: RUN TIME | E13: LABOR RATE | F13: ='Top Assy'!F13 -> 10 | G13: ='Top Assy'!G13 -> 25 | H13: ='Top Assy'!H13 -> 50 | I13: ='Top Assy'!I13 -> 75 | J13: ='Top Assy'!J13 -> 100 | K13: ='Top Assy'!K13 -> 250 | L13: ='Top Assy'!L13 -> 500 | M13: ='Top Assy'!M13 -> 1000 | N13: 1
A14: Program | E14: 0 | N14: =(($B14/N$13*$E14)+($C14*$E14)) -> 0
A15: Fixtures | E15: 0 | N15: =(($B15/N$13*$E15)+($C15*$E15)) -> 0
A16: Mill/Turn | E16: 0 | F16: =(($B16/F$13*$E16)+($C16*$E16)) -> 0 | G16: =(($B16/G$13*$E16)+($C16*$E16)) -> 0 | H16: =(($B16/H$13*$E16)+($C16*$E16)) -> 0 | I16: =(($B16/I$13*$E16)+($C16*$E16)) -> 0 | J16: =(($B16/J$13*$E16)+($C16*$E16)) -> 0 | K16: =(($B16/K$13*$E16)+($C16*$E16)) -> 0 | L16: =(($B16/L$13*$E16)+($C16*$E16)) -> 0 | M16: =(($B16/M$13*$E16)+($C16*$E16)) -> 0
A17: Metals - Mills | E17: 0 | F17: =(($B17/F$13*$E17)+($C17*$E17)) -> 0 | G17: =(($B17/G$13*$E17)+($C17*$E17)) -> 0 | H17: =(($B17/H$13*$E17)+($C17*$E17)) -> 0 | I17: =(($B17/I$13*$E17)+($C17*$E17)) -> 0 | J17: =(($B17/J$13*$E17)+($C17*$E17)) -> 0 | K17: =(($B17/K$13*$E17)+($C17*$E17)) -> 0 | L17: =(($B17/L$13*$E17)+($C17*$E17)) -> 0 | M17: =(($B17/M$13*$E17)+($C17*$E17)) -> 0
A18: Metals - Lathe | E18: 0 | F18: =(($B18/F$13*$E18)+($C18*$E18)) -> 0 | G18: =(($B18/G$13*$E18)+($C18*$E18)) -> 0 | H18: =(($B18/H$13*$E18)+($C18*$E18)) -> 0 | I18: =(($B18/I$13*$E18)+($C18*$E18)) -> 0 | J18: =(($B18/J$13*$E18)+($C18*$E18)) -> 0 | K18: =(($B18/K$13*$E18)+($C18*$E18)) -> 0 | L18: =(($B18/L$13*$E18)+($C18*$E18)) -> 0 | M18: =(($B18/M$13*$E18)+($C18*$E18)) -> 0
A19: Rubber Mold | E19: 0 | F19: =(($B19/F$13*$E19)+($C19*$E19)) -> 0 | G19: =(($B19/G$13*$E19)+($C19*$E19)) -> 0 | H19: =(($B19/H$13*$E19)+($C19*$E19)) -> 0 | I19: =(($B19/I$13*$E19)+($C19*$E19)) -> 0 | J19: =(($B19/J$13*$E19)+($C19*$E19)) -> 0 | K19: =(($B19/K$13*$E19)+($C19*$E19)) -> 0 | L19: =(($B19/L$13*$E19)+($C19*$E19)) -> 0 | M19: =(($B19/M$13*$E19)+($C19*$E19)) -> 0
A20: Plastic Injection Mold | E20: 0 | F20: =(($B20/F$13*$E20)+($C20*$E20)) -> 0 | G20: =(($B20/G$13*$E20)+($C20*$E20)) -> 0 | H20: =(($B20/H$13*$E20)+($C20*$E20)) -> 0 | I20: =(($B20/I$13*$E20)+($C20*$E20)) -> 0 | J20: =(($B20/J$13*$E20)+($C20*$E20)) -> 0 | K20: =(($B20/K$13*$E20)+($C20*$E20)) -> 0 | L20: =(($B20/L$13*$E20)+($C20*$E20)) -> 0 | M20: =(($B20/M$13*$E20)+($C20*$E20)) -> 0
A21: Plastic Compression Mold | E21: 0 | F21: =(($B21/F$13*$E21)+($C21*$E21)) -> 0 | G21: =(($B21/G$13*$E21)+($C21*$E21)) -> 0 | H21: =(($B21/H$13*$E21)+($C21*$E21)) -> 0 | I21: =(($B21/I$13*$E21)+($C21*$E21)) -> 0 | J21: =(($B21/J$13*$E21)+($C21*$E21)) -> 0 | K21: =(($B21/K$13*$E21)+($C21*$E21)) -> 0 | L21: =(($B21/L$13*$E21)+($C21*$E21)) -> 0 | M21: =(($B21/M$13*$E21)+($C21*$E21)) -> 0
A22: Waterjet - Setup | E22: 0 | F22: =(($B22/F$13*$E22)+($C22*$E22)) -> 0 | G22: =(($B22/G$13*$E22)+($C22*$E22)) -> 0 | H22: =(($B22/H$13*$E22)+($C22*$E22)) -> 0 | I22: =(($B22/I$13*$E22)+($C22*$E22)) -> 0 | J22: =(($B22/J$13*$E22)+($C22*$E22)) -> 0 | K22: =(($B22/K$13*$E22)+($C22*$E22)) -> 0 | L22: =(($B22/L$13*$E22)+($C22*$E22)) -> 0 | M22: =(($B22/M$13*$E22)+($C22*$E22)) -> 0
A23: Waterjet - Operator | E23: 0 | F23: =(($B23/F$13*$E23)+($C23*$E23)) -> 0 | G23: =(($B23/G$13*$E23)+($C23*$E23)) -> 0 | H23: =(($B23/H$13*$E23)+($C23*$E23)) -> 0 | I23: =(($B23/I$13*$E23)+($C23*$E23)) -> 0 | J23: =(($B23/J$13*$E23)+($C23*$E23)) -> 0 | K23: =(($B23/K$13*$E23)+($C23*$E23)) -> 0 | L23: =(($B23/L$13*$E23)+($C23*$E23)) -> 0 | M23: =(($B23/M$13*$E23)+($C23*$E23)) -> 0
A24: Assembly, Die Punch, Deburr | E24: 0 | F24: =(($B24/F$13*$E24)+($C24*$E24)) -> 0 | G24: =(($B24/G$13*$E24)+($C24*$E24)) -> 0 | H24: =(($B24/H$13*$E24)+($C24*$E24)) -> 0 | I24: =(($B24/I$13*$E24)+($C24*$E24)) -> 0 | J24: =(($B24/J$13*$E24)+($C24*$E24)) -> 0 | K24: =(($B24/K$13*$E24)+($C24*$E24)) -> 0 | L24: =(($B24/L$13*$E24)+($C24*$E24)) -> 0 | M24: =(($B24/M$13*$E24)+($C24*$E24)) -> 0
A25: Quality Inspection | E25: 0 | F25: =(($B25/F$13*$E25)+($C25*$E25)) -> 0 | G25: =(($B25/G$13*$E25)+($C25*$E25)) -> 0 | H25: =(($B25/H$13*$E25)+($C25*$E25)) -> 0 | I25: =(($B25/I$13*$E25)+($C25*$E25)) -> 0 | J25: =(($B25/J$13*$E25)+($C25*$E25)) -> 0 | K25: =(($B25/K$13*$E25)+($C25*$E25)) -> 0 | L25: =(($B25/L$13*$E25)+($C25*$E25)) -> 0 | M25: =(($B25/M$13*$E25)+($C25*$E25)) -> 0
C26: Labor | E26: Basic LABOR | F26: =SUM(F16:F25) -> 0 | G26: =SUM(G16:G25) -> 0 | H26: =SUM(H16:H25) -> 0 | I26: =SUM(I16:I25) -> 0 | J26: =SUM(J16:J25) -> 0 | K26: =SUM(K16:K25) -> 0 | L26: =SUM(L16:L25) -> 0 | M26: =SUM(M16:M25) -> 0 | N26: =SUM(N14:N25) -> 0
B27: T. setup | C27: T.RUN | E27: hrs | F27: =(($B$28/F13)+$C$28)/60 -> 0 | G27: =(($B$28/G13)+$C$28)/60 -> 0 | H27: =(($B$28/H13)+$C$28)/60 -> 0 | I27: =(($B$28/I13)+$C$28)/60 -> 0 | J27: =(($B$28/J13)+$C$28)/60 -> 0 | K27: =(($B$28/K13)+$C$28)/60 -> 0 | L27: =(($B$28/L13)+$C$28)/60 -> 0 | M27: =(($B$28/M13)+$C$28)/60 -> 0
B28: =SUM(B16:B25) -> 0 | C28: =SUM(C16:C25) -> 0 | D28: 0 | E28: BURDEN | F28: =F26*$D$28 -> 0 | G28: =G26*$D$28 -> 0 | H28: =H26*$D$28 -> 0 | I28: =I26*$D$28 -> 0 | J28: =J26*$D$28 -> 0 | K28: =K26*$D$28 -> 0 | L28: =L26*$D$28 -> 0 | M28: =M26*$D$28 -> 0
E30: Total | F30: =F26+F28 -> 0 | G30: =G26+G28 -> 0 | H30: =H26+H28 -> 0 | I30: =I26+I28 -> 0 | J30: =J26+J28 -> 0 | K30: =K26+K28 -> 0 | L30: =L26+L28 -> 0 | M30: =M26+M28 -> 0 | N30: =N26 -> 0
A32: RAW MATERIALS & HARDWARE | B32: Matl UoM | C32: PARTS QTY | D32: UNIT PRICE | E32: MAT'l BURDEN | F32: ="Qty: "& F13 -> Qty: 10 | G32: ="Qty: "& G13 -> Qty: 25 | H32: ="Qty: "& H13 -> Qty: 50 | I32: ="Qty: "& I13 -> Qty: 75 | J32: ="Qty: "& J13 -> Qty: 100 | K32: ="Qty: "& K13 -> Qty: 250 | L32: ="Qty: "& L13 -> Qty: 500 | M32: ="Qty: "& M13 -> Qty: 1000 | N32: Amortize/ Min Buy
E33: =C33*D33 -> 0 | F33: =IF($N33=TRUE,$E33/F$13,$E33*(1+(1/F$13))) -> 0 | G33: =IF($N33=TRUE,$E33/G$13,$E33*(1+(1/G$13))) -> 0 | H33: =IF($N33=TRUE,$E33/H$13,$E33*(1+(1/H$13))) -> 0 | I33: =IF($N33=TRUE,$E33/I$13,$E33*(1+(1/I$13))) -> 0 | J33: =IF($N33=TRUE,$E33/J$13,$E33*(1+(1/J$13))) -> 0 | K33: =IF($N33=TRUE,$E33/K$13,$E33*(1+(1/K$13))) -> 0 | L33: =IF($N33=TRUE,$E33/L$13,$E33*(1+(1/L$13))) -> 0 | M33: =IF($N33=TRUE,$E33/M$13,$E33*(1+(1/M$13))) -> 0 | N33: FALSE
E34: =C34*D34 -> 0 | F34: =IF($N34=TRUE,$E34/F$13,$E34*(1+(1/F$13))) -> 0 | G34: =IF($N34=TRUE,$E34/G$13,$E34*(1+(1/G$13))) -> 0 | H34: =IF($N34=TRUE,$E34/H$13,$E34*(1+(1/H$13))) -> 0 | I34: =IF($N34=TRUE,$E34/I$13,$E34*(1+(1/I$13))) -> 0 | J34: =IF($N34=TRUE,$E34/J$13,$E34*(1+(1/J$13))) -> 0 | K34: =IF($N34=TRUE,$E34/K$13,$E34*(1+(1/K$13))) -> 0 | L34: =IF($N34=TRUE,$E34/L$13,$E34*(1+(1/L$13))) -> 0 | M34: =IF($N34=TRUE,$E34/M$13,$E34*(1+(1/M$13))) -> 0 | N34: FALSE
E35: =C35*D35 -> 0 | F35: =IF($N35=TRUE,$E35/F$13,$E35*(1+(1/F$13))) -> 0 | G35: =IF($N35=TRUE,$E35/G$13,$E35*(1+(1/G$13))) -> 0 | H35: =IF($N35=TRUE,$E35/H$13,$E35*(1+(1/H$13))) -> 0 | I35: =IF($N35=TRUE,$E35/I$13,$E35*(1+(1/I$13))) -> 0 | J35: =IF($N35=TRUE,$E35/J$13,$E35*(1+(1/J$13))) -> 0 | K35: =IF($N35=TRUE,$E35/K$13,$E35*(1+(1/K$13))) -> 0 | L35: =IF($N35=TRUE,$E35/L$13,$E35*(1+(1/L$13))) -> 0 | M35: =IF($N35=TRUE,$E35/M$13,$E35*(1+(1/M$13))) -> 0 | N35: FALSE | S35: QTY | T35: Total
E36: =C36*D36 -> 0 | F36: =IF($N36=TRUE,$E36/F$13,$E36*(1+(1/F$13))) -> 0 | G36: =IF($N36=TRUE,$E36/G$13,$E36*(1+(1/G$13))) -> 0 | H36: =IF($N36=TRUE,$E36/H$13,$E36*(1+(1/H$13))) -> 0 | I36: =IF($N36=TRUE,$E36/I$13,$E36*(1+(1/I$13))) -> 0 | J36: =IF($N36=TRUE,$E36/J$13,$E36*(1+(1/J$13))) -> 0 | K36: =IF($N36=TRUE,$E36/K$13,$E36*(1+(1/K$13))) -> 0 | L36: =IF($N36=TRUE,$E36/L$13,$E36*(1+(1/L$13))) -> 0 | M36: =IF($N36=TRUE,$E36/M$13,$E36*(1+(1/M$13))) -> 0 | N36: FALSE | S36: =M13 -> 1000 | T36: =M63 -> 0
E37: =C37*D37 -> 0 | F37: =IF($N37=TRUE,$E37/F$13,$E37*(1+(1/F$13))) -> 0 | G37: =IF($N37=TRUE,$E37/G$13,$E37*(1+(1/G$13))) -> 0 | H37: =IF($N37=TRUE,$E37/H$13,$E37*(1+(1/H$13))) -> 0 | I37: =IF($N37=TRUE,$E37/I$13,$E37*(1+(1/I$13))) -> 0 | J37: =IF($N37=TRUE,$E37/J$13,$E37*(1+(1/J$13))) -> 0 | K37: =IF($N37=TRUE,$E37/K$13,$E37*(1+(1/K$13))) -> 0 | L37: =IF($N37=TRUE,$E37/L$13,$E37*(1+(1/L$13))) -> 0 | M37: =IF($N37=TRUE,$E37/M$13,$E37*(1+(1/M$13))) -> 0 | N37: FALSE | S37: =L13 -> 500 | T37: =L63 -> 0
E38: =C38*D38 -> 0 | F38: =IF($N38=TRUE,$E38/F$13,$E38*(1+(1/F$13))) -> 0 | G38: =IF($N38=TRUE,$E38/G$13,$E38*(1+(1/G$13))) -> 0 | H38: =IF($N38=TRUE,$E38/H$13,$E38*(1+(1/H$13))) -> 0 | I38: =IF($N38=TRUE,$E38/I$13,$E38*(1+(1/I$13))) -> 0 | J38: =IF($N38=TRUE,$E38/J$13,$E38*(1+(1/J$13))) -> 0 | K38: =IF($N38=TRUE,$E38/K$13,$E38*(1+(1/K$13))) -> 0 | L38: =IF($N38=TRUE,$E38/L$13,$E38*(1+(1/L$13))) -> 0 | M38: =IF($N38=TRUE,$E38/M$13,$E38*(1+(1/M$13))) -> 0 | N38: FALSE | S38: =I13 -> 75 | T38: =I63 -> 0
E39: =C39*D39 -> 0 | F39: =IF($N39=TRUE,$E39/F$13,$E39*(1+(1/F$13))) -> 0 | G39: =IF($N39=TRUE,$E39/G$13,$E39*(1+(1/G$13))) -> 0 | H39: =IF($N39=TRUE,$E39/H$13,$E39*(1+(1/H$13))) -> 0 | I39: =IF($N39=TRUE,$E39/I$13,$E39*(1+(1/I$13))) -> 0 | J39: =IF($N39=TRUE,$E39/J$13,$E39*(1+(1/J$13))) -> 0 | K39: =IF($N39=TRUE,$E39/K$13,$E39*(1+(1/K$13))) -> 0 | L39: =IF($N39=TRUE,$E39/L$13,$E39*(1+(1/L$13))) -> 0 | M39: =IF($N39=TRUE,$E39/M$13,$E39*(1+(1/M$13))) -> 0 | S39: =H13 -> 50 | T39: =H63 -> 0
E40: =C40*D40 -> 0 | F40: =IF($N40=TRUE,$E40/F$13,$E40*(1+(1/F$13))) -> 0 | G40: =IF($N40=TRUE,$E40/G$13,$E40*(1+(1/G$13))) -> 0 | H40: =IF($N40=TRUE,$E40/H$13,$E40*(1+(1/H$13))) -> 0 | I40: =IF($N40=TRUE,$E40/I$13,$E40*(1+(1/I$13))) -> 0 | J40: =IF($N40=TRUE,$E40/J$13,$E40*(1+(1/J$13))) -> 0 | K40: =IF($N40=TRUE,$E40/K$13,$E40*(1+(1/K$13))) -> 0 | L40: =IF($N40=TRUE,$E40/L$13,$E40*(1+(1/L$13))) -> 0 | M40: =IF($N40=TRUE,$E40/M$13,$E40*(1+(1/M$13))) -> 0 | N40: FALSE | S40: =G13 -> 25 | T40: =G63 -> 0
E41: =C41*D41 -> 0 | F41: =IF($N41=TRUE,$E41/F$13,$E41*(1+(1/F$13))) -> 0 | G41: =IF($N41=TRUE,$E41/G$13,$E41*(1+(1/G$13))) -> 0 | H41: =IF($N41=TRUE,$E41/H$13,$E41*(1+(1/H$13))) -> 0 | I41: =IF($N41=TRUE,$E41/I$13,$E41*(1+(1/I$13))) -> 0 | J41: =IF($N41=TRUE,$E41/J$13,$E41*(1+(1/J$13))) -> 0 | K41: =IF($N41=TRUE,$E41/K$13,$E41*(1+(1/K$13))) -> 0 | L41: =IF($N41=TRUE,$E41/L$13,$E41*(1+(1/L$13))) -> 0 | M41: =IF($N41=TRUE,$E41/M$13,$E41*(1+(1/M$13))) -> 0 | N41: FALSE | S41: =F13 -> 10 | T41: =F63 -> 0
E42: =C42*D42 -> 0 | F42: =IF($N42=TRUE,$E42/F$13,$E42*(1+(1/F$13))) -> 0 | G42: =IF($N42=TRUE,$E42/G$13,$E42*(1+(1/G$13))) -> 0 | H42: =IF($N42=TRUE,$E42/H$13,$E42*(1+(1/H$13))) -> 0 | I42: =IF($N42=TRUE,$E42/I$13,$E42*(1+(1/I$13))) -> 0 | J42: =IF($N42=TRUE,$E42/J$13,$E42*(1+(1/J$13))) -> 0 | K42: =IF($N42=TRUE,$E42/K$13,$E42*(1+(1/K$13))) -> 0 | L42: =IF($N42=TRUE,$E42/L$13,$E42*(1+(1/L$13))) -> 0 | M42: =IF($N42=TRUE,$E42/M$13,$E42*(1+(1/M$13))) -> 0 | N42: FALSE
E43: =C43*D43 -> 0 | F43: =IF($N43=TRUE,$E43/F$13,$E43*(1+(1/F$13))) -> 0 | G43: =IF($N43=TRUE,$E43/G$13,$E43*(1+(1/G$13))) -> 0 | H43: =IF($N43=TRUE,$E43/H$13,$E43*(1+(1/H$13))) -> 0 | I43: =IF($N43=TRUE,$E43/I$13,$E43*(1+(1/I$13))) -> 0 | J43: =IF($N43=TRUE,$E43/J$13,$E43*(1+(1/J$13))) -> 0 | K43: =IF($N43=TRUE,$E43/K$13,$E43*(1+(1/K$13))) -> 0 | L43: =IF($N43=TRUE,$E43/L$13,$E43*(1+(1/L$13))) -> 0 | M43: =IF($N43=TRUE,$E43/M$13,$E43*(1+(1/M$13))) -> 0 | N43: FALSE
E44: =C44*D44 -> 0 | F44: =IF($N44=TRUE,$E44/F$13,$E44*(1+(1/F$13))) -> 0 | G44: =IF($N44=TRUE,$E44/G$13,$E44*(1+(1/G$13))) -> 0 | H44: =IF($N44=TRUE,$E44/H$13,$E44*(1+(1/H$13))) -> 0 | I44: =IF($N44=TRUE,$E44/I$13,$E44*(1+(1/I$13))) -> 0 | J44: =IF($N44=TRUE,$E44/J$13,$E44*(1+(1/J$13))) -> 0 | K44: =IF($N44=TRUE,$E44/K$13,$E44*(1+(1/K$13))) -> 0 | L44: =IF($N44=TRUE,$E44/L$13,$E44*(1+(1/L$13))) -> 0 | M44: =IF($N44=TRUE,$E44/M$13,$E44*(1+(1/M$13))) -> 0 | N44: FALSE
A45: PROCESSES/COMPONENTS | D45: SETUP $ | E45: RUN$ EA.
F46: =($D46/F$13)+$E46 -> 0 | G46: =($D46/G$13)+$E46 -> 0 | H46: =($D46/H$13)+$E46 -> 0 | I46: =($D46/I$13)+$E46 -> 0 | J46: =($D46/J$13)+$E46 -> 0 | K46: =($D46/K$13)+$E46 -> 0 | L46: =($D46/L$13)+$E46 -> 0 | M46: =($D46/M$13)+$E46 -> 0
...

Sheet Subassy 2
A2: CUSTOMER: | F2: Comments:
A3: P/N: | B3: 2 | D3: NSN #:
A4: REV: | D4: SOL #:
A5: QUOTE LOG No.: | D5: RFQ #:
A6: QTY: | B6: =F13&", "&G13&", "&H13&", "&I13&", "&J13&", "&K13&", "&L13&", "&M13 -> 10, 25, 50, 75, 100, 250, 500, 1000
A7: DATE:
A8: ESTIMATOR:
A11: MANUFACTURING OPERATIONS | F11: COST ESTIMATED QUANTITIES | N11: NRE/SET-UP
B13: SET-UP TIME | C13: RUN TIME | E13: LABOR RATE | F13: ='Top Assy'!F13 -> 10 | G13: ='Top Assy'!G13 -> 25 | H13: ='Top Assy'!H13 -> 50 | I13: ='Top Assy'!I13 -> 75 | J13: ='Top Assy'!J13 -> 100 | K13: ='Top Assy'!K13 -> 250 | L13: ='Top Assy'!L13 -> 500 | M13: ='Top Assy'!M13 -> 1000 | N13: 1
A14: Program | E14: 0 | N14: =(($B14/N$13*$E14)+($C14*$E14)) -> 0
A15: Fixtures | E15: 0 | N15: =(($B15/N$13*$E15)+($C15*$E15)) -> 0
A16: Mill/Turn | E16: 0 | F16: =(($B16/F$13*$E16)+($C16*$E16)) -> 0 | G16: =(($B16/G$13*$E16)+($C16*$E16)) -> 0 | H16: =(($B16/H$13*$E16)+($C16*$E16)) -> 0 | I16: =(($B16/I$13*$E16)+($C16*$E16)) -> 0 | J16: =(($B16/J$13*$E16)+($C16*$E16)) -> 0 | K16: =(($B16/K$13*$E16)+($C16*$E16)) -> 0 | L16: =(($B16/L$13*$E16)+($C16*$E16)) -> 0 | M16: =(($B16/M$13*$E16)+($C16*$E16)) -> 0
A17: Metals - Mills | E17: 0 | F17: =(($B17/F$13*$E17)+($C17*$E17)) -> 0 | G17: =(($B17/G$13*$E17)+($C17*$E17)) -> 0 | H17: =(($B17/H$13*$E17)+($C17*$E17)) -> 0 | I17: =(($B17/I$13*$E17)+($C17*$E17)) -> 0 | J17: =(($B17/J$13*$E17)+($C17*$E17)) -> 0 | K17: =(($B17/K$13*$E17)+($C17*$E17)) -> 0 | L17: =(($B17/L$13*$E17)+($C17*$E17)) -> 0 | M17: =(($B17/M$13*$E17)+($C17*$E17)) -> 0
A18: Metals - Lathe | E18: 0 | F18: =(($B18/F$13*$E18)+($C18*$E18)) -> 0 | G18: =(($B18/G$13*$E18)+($C18*$E18)) -> 0 | H18: =(($B18/H$13*$E18)+($C18*$E18)) -> 0 | I18: =(($B18/I$13*$E18)+($C18*$E18)) -> 0 | J18: =(($B18/J$13*$E18)+($C18*$E18)) -> 0 | K18: =(($B18/K$13*$E18)+($C18*$E18)) -> 0 | L18: =(($B18/L$13*$E18)+($C18*$E18)) -> 0 | M18: =(($B18/M$13*$E18)+($C18*$E18)) -> 0
A19: Rubber Mold | E19: 0 | F19: =(($B19/F$13*$E19)+($C19*$E19)) -> 0 | G19: =(($B19/G$13*$E19)+($C19*$E19)) -> 0 | H19: =(($B19/H$13*$E19)+($C19*$E19)) -> 0 | I19: =(($B19/I$13*$E19)+($C19*$E19)) -> 0 | J19: =(($B19/J$13*$E19)+($C19*$E19)) -> 0 | K19: =(($B19/K$13*$E19)+($C19*$E19)) -> 0 | L19: =(($B19/L$13*$E19)+($C19*$E19)) -> 0 | M19: =(($B19/M$13*$E19)+($C19*$E19)) -> 0
A20: Plastic Injection Mold | E20: 0 | F20: =(($B20/F$13*$E20)+($C20*$E20)) -> 0 | G20: =(($B20/G$13*$E20)+($C20*$E20)) -> 0 | H20: =(($B20/H$13*$E20)+($C20*$E20)) -> 0 | I20: =(($B20/I$13*$E20)+($C20*$E20)) -> 0 | J20: =(($B20/J$13*$E20)+($C20*$E20)) -> 0 | K20: =(($B20/K$13*$E20)+($C20*$E20)) -> 0 | L20: =(($B20/L$13*$E20)+($C20*$E20)) -> 0 | M20: =(($B20/M$13*$E20)+($C20*$E20)) -> 0
A21: Plastic Compression Mold | E21: 0 | F21: =(($B21/F$13*$E21)+($C21*$E21)) -> 0 | G21: =(($B21/G$13*$E21)+($C21*$E21)) -> 0 | H21: =(($B21/H$13*$E21)+($C21*$E21)) -> 0 | I21: =(($B21/I$13*$E21)+($C21*$E21)) -> 0 | J21: =(($B21/J$13*$E21)+($C21*$E21)) -> 0 | K21: =(($B21/K$13*$E21)+($C21*$E21)) -> 0 | L21: =(($B21/L$13*$E21)+($C21*$E21)) -> 0 | M21: =(($B21/M$13*$E21)+($C21*$E21)) -> 0
A22: Waterjet - Setup | E22: 0 | F22: =(($B22/F$13*$E22)+($C22*$E22)) -> 0 | G22: =(($B22/G$13*$E22)+($C22*$E22)) -> 0 | H22: =(($B22/H$13*$E22)+($C22*$E22)) -> 0 | I22: =(($B22/I$13*$E22)+($C22*$E22)) -> 0 | J22: =(($B22/J$13*$E22)+($C22*$E22)) -> 0 | K22: =(($B22/K$13*$E22)+($C22*$E22)) -> 0 | L22: =(($B22/L$13*$E22)+($C22*$E22)) -> 0 | M22: =(($B22/M$13*$E22)+($C22*$E22)) -> 0
A23: Waterjet - Operator | E23: 0 | F23: =(($B23/F$13*$E23)+($C23*$E23)) -> 0 | G23: =(($B23/G$13*$E23)+($C23*$E23)) -> 0 | H23: =(($B23/H$13*$E23)+($C23*$E23)) -> 0 | I23: =(($B23/I$13*$E23)+($C23*$E23)) -> 0 | J23: =(($B23/J$13*$E23)+($C23*$E23)) -> 0 | K23: =(($B23/K$13*$E23)+($C23*$E23)) -> 0 | L23: =(($B23/L$13*$E23)+($C23*$E23)) -> 0 | M23: =(($B23/M$13*$E23)+($C23*$E23)) -> 0
A24: Assembly, Die Punch, Deburr | E24: 0 | F24: =(($B24/F$13*$E24)+($C24*$E24)) -> 0 | G24: =(($B24/G$13*$E24)+($C24*$E24)) -> 0 | H24: =(($B24/H$13*$E24)+($C24*$E24)) -> 0 | I24: =(($B24/I$13*$E24)+($C24*$E24)) -> 0 | J24: =(($B24/J$13*$E24)+($C24*$E24)) -> 0 | K24: =(($B24/K$13*$E24)+($C24*$E24)) -> 0 | L24: =(($B24/L$13*$E24)+($C24*$E24)) -> 0 | M24: =(($B24/M$13*$E24)+($C24*$E24)) -> 0
A25: Quality Inspection | E25: 0 | F25: =(($B25/F$13*$E25)+($C25*$E25)) -> 0 | G25: =(($B25/G$13*$E25)+($C25*$E25)) -> 0 | H25: =(($B25/H$13*$E25)+($C25*$E25)) -> 0 | I25: =(($B25/I$13*$E25)+($C25*$E25)) -> 0 | J25: =(($B25/J$13*$E25)+($C25*$E25)) -> 0 | K25: =(($B25/K$13*$E25)+($C25*$E25)) -> 0 | L25: =(($B25/L$13*$E25)+($C25*$E25)) -> 0 | M25: =(($B25/M$13*$E25)+($C25*$E25)) -> 0
C26: Labor | E26: Basic LABOR | F26: =SUM(F16:F25) -> 0 | G26: =SUM(G16:G25) -> 0 | H26: =SUM(H16:H25) -> 0 | I26: =SUM(I16:I25) -> 0 | J26: =SUM(J16:J25) -> 0 | K26: =SUM(K16:K25) -> 0 | L26: =SUM(L16:L25) -> 0 | M26: =SUM(M16:M25) -> 0 | N26: =SUM(N14:N25) -> 0
B27: T. setup | C27: T.RUN | E27: hrs | F27: =(($B$28/F13)+$C$28)/60 -> 0 | G27: =(($B$28/G13)+$C$28)/60 -> 0 | H27: =(($B$28/H13)+$C$28)/60 -> 0 | I27: =(($B$28/I13)+$C$28)/60 -> 0 | J27: =(($B$28/J13)+$C$28)/60 -> 0 | K27: =(($B$28/K13)+$C$28)/60 -> 0 | L27: =(($B$28/L13)+$C$28)/60 -> 0 | M27: =(($B$28/M13)+$C$28)/60 -> 0
B28: =SUM(B16:B25) -> 0 | C28: =SUM(C16:C25) -> 0 | D28: 0 | E28: BURDEN | F28: =F26*$D$28 -> 0 | G28: =G26*$D$28 -> 0 | H28: =H26*$D$28 -> 0 | I28: =I26*$D$28 -> 0 | J28: =J26*$D$28 -> 0 | K28: =K26*$D$28 -> 0 | L28: =L26*$D$28 -> 0 | M28: =M26*$D$28 -> 0
E30: Total | F30: =F26+F28 -> 0 | G30: =G26+G28 -> 0 | H30: =H26+H28 -> 0 | I30: =I26+I28 -> 0 | J30: =J26+J28 -> 0 | K30: =K26+K28 -> 0 | L30: =L26+L28 -> 0 | M30: =M26+M28 -> 0 | N30: =N26 -> 0
A32: RAW MATERIALS & HARDWARE | B32: Matl UoM | C32: PARTS QTY | D32: UNIT PRICE | E32: MAT'l BURDEN | F32: ="Qty: "& F13 -> Qty: 10 | G32: ="Qty: "& G13 -> Qty: 25 | H32: ="Qty: "& H13 -> Qty: 50 | I32: ="Qty: "& I13 -> Qty: 75 | J32: ="Qty: "& J13 -> Qty: 100 | K32: ="Qty: "& K13 -> Qty: 250 | L32: ="Qty: "& L13 -> Qty: 500 | M32: ="Qty: "& M13 -> Qty: 1000 | N32: Amortize/ Min Buy
E33: =C33*D33 -> 0 | F33: =IF($N33=TRUE,$E33/F$13,$E33*(1+(1/F$13))) -> 0 | G33: =IF($N33=TRUE,$E33/G$13,$E33*(1+(1/G$13))) -> 0 | H33: =IF($N33=TRUE,$E33/H$13,$E33*(1+(1/H$13))) -> 0 | I33: =IF($N33=TRUE,$E33/I$13,$E33*(1+(1/I$13))) -> 0 | J33: =IF($N33=TRUE,$E33/J$13,$E33*(1+(1/J$13))) -> 0 | K33: =IF($N33=TRUE,$E33/K$13,$E33*(1+(1/K$13))) -> 0 | L33: =IF($N33=TRUE,$E33/L$13,$E33*(1+(1/L$13))) -> 0 | M33: =IF($N33=TRUE,$E33/M$13,$E33*(1+(1/M$13))) -> 0 | N33: FALSE
E34: =C34*D34 -> 0 | F34: =IF($N34=TRUE,$E34/F$13,$E34*(1+(1/F$13))) -> 0 | G34: =IF($N34=TRUE,$E34/G$13,$E34*(1+(1/G$13))) -> 0 | H34: =IF($N34=TRUE,$E34/H$13,$E34*(1+(1/H$13))) -> 0 | I34: =IF($N34=TRUE,$E34/I$13,$E34*(1+(1/I$13))) -> 0 | J34: =IF($N34=TRUE,$E34/J$13,$E34*(1+(1/J$13))) -> 0 | K34: =IF($N34=TRUE,$E34/K$13,$E34*(1+(1/K$13))) -> 0 | L34: =IF($N34=TRUE,$E34/L$13,$E34*(1+(1/L$13))) -> 0 | M34: =IF($N34=TRUE,$E34/M$13,$E34*(1+(1/M$13))) -> 0 | N34: FALSE
E35: =C35*D35 -> 0 | F35: =IF($N35=TRUE,$E35/F$13,$E35*(1+(1/F$13))) -> 0 | G35: =IF($N35=TRUE,$E35/G$13,$E35*(1+(1/G$13))) -> 0 | H35: =IF($N35=TRUE,$E35/H$13,$E35*(1+(1/H$13))) -> 0 | I35: =IF($N35=TRUE,$E35/I$13,$E35*(1+(1/I$13))) -> 0 | J35: =IF($N35=TRUE,$E35/J$13,$E35*(1+(1/J$13))) -> 0 | K35: =IF($N35=TRUE,$E35/K$13,$E35*(1+(1/K$13))) -> 0 | L35: =IF($N35=TRUE,$E35/L$13,$E35*(1+(1/L$13))) -> 0 | M35: =IF($N35=TRUE,$E35/M$13,$E35*(1+(1/M$13))) -> 0 | N35: FALSE | S35: QTY | T35: Total
E36: =C36*D36 -> 0 | F36: =IF($N36=TRUE,$E36/F$13,$E36*(1+(1/F$13))) -> 0 | G36: =IF($N36=TRUE,$E36/G$13,$E36*(1+(1/G$13))) -> 0 | H36: =IF($N36=TRUE,$E36/H$13,$E36*(1+(1/H$13))) -> 0 | I36: =IF($N36=TRUE,$E36/I$13,$E36*(1+(1/I$13))) -> 0 | J36: =IF($N36=TRUE,$E36/J$13,$E36*(1+(1/J$13))) -> 0 | K36: =IF($N36=TRUE,$E36/K$13,$E36*(1+(1/K$13))) -> 0 | L36: =IF($N36=TRUE,$E36/L$13,$E36*(1+(1/L$13))) -> 0 | M36: =IF($N36=TRUE,$E36/M$13,$E36*(1+(1/M$13))) -> 0 | N36: FALSE | S36: =M13 -> 1000 | T36: =M63 -> 0
E37: =C37*D37 -> 0 | F37: =IF($N37=TRUE,$E37/F$13,$E37*(1+(1/F$13))) -> 0 | G37: =IF($N37=TRUE,$E37/G$13,$E37*(1+(1/G$13))) -> 0 | H37: =IF($N37=TRUE,$E37/H$13,$E37*(1+(1/H$13))) -> 0 | I37: =IF($N37=TRUE,$E37/I$13,$E37*(1+(1/I$13))) -> 0 | J37: =IF($N37=TRUE,$E37/J$13,$E37*(1+(1/J$13))) -> 0 | K37: =IF($N37=TRUE,$E37/K$13,$E37*(1+(1/K$13))) -> 0 | L37: =IF($N37=TRUE,$E37/L$13,$E37*(1+(1/L$13))) -> 0 | M37: =IF($N37=TRUE,$E37/M$13,$E37*(1+(1/M$13))) -> 0 | N37: FALSE | S37: =L13 -> 500 | T37: =L63 -> 0
E38: =C38*D38 -> 0 | F38: =IF($N38=TRUE,$E38/F$13,$E38*(1+(1/F$13))) -> 0 | G38: =IF($N38=TRUE,$E38/G$13,$E38*(1+(1/G$13))) -> 0 | H38: =IF($N38=TRUE,$E38/H$13,$E38*(1+(1/H$13))) -> 0 | I38: =IF($N38=TRUE,$E38/I$13,$E38*(1+(1/I$13))) -> 0 | J38: =IF($N38=TRUE,$E38/J$13,$E38*(1+(1/J$13))) -> 0 | K38: =IF($N38=TRUE,$E38/K$13,$E38*(1+(1/K$13))) -> 0 | L38: =IF($N38=TRUE,$E38/L$13,$E38*(1+(1/L$13))) -> 0 | M38: =IF($N38=TRUE,$E38/M$13,$E38*(1+(1/M$13))) -> 0 | N38: FALSE | S38: =K13 -> 250 | T38: =K63 -> 0
E39: =C39*D39 -> 0 | F39: =IF($N39=TRUE,$E39/F$13,$E39*(1+(1/F$13))) -> 0 | G39: =IF($N39=TRUE,$E39/G$13,$E39*(1+(1/G$13))) -> 0 | H39: =IF($N39=TRUE,$E39/H$13,$E39*(1+(1/H$13))) -> 0 | I39: =IF($N39=TRUE,$E39/I$13,$E39*(1+(1/I$13))) -> 0 | J39: =IF($N39=TRUE,$E39/J$13,$E39*(1+(1/J$13))) -> 0 | K39: =IF($N39=TRUE,$E39/K$13,$E39*(1+(1/K$13))) -> 0 | L39: =IF($N39=TRUE,$E39/L$13,$E39*(1+(1/L$13))) -> 0 | M39: =IF($N39=TRUE,$E39/M$13,$E39*(1+(1/M$13))) -> 0 | N39: FALSE | S39: =H13 -> 50 | T39: =H63 -> 0
E40: =C40*D40 -> 0 | F40: =IF($N40=TRUE,$E40/F$13,$E40*(1+(1/F$13))) -> 0 | G40: =IF($N40=TRUE,$E40/G$13,$E40*(1+(1/G$13))) -> 0 | H40: =IF($N40=TRUE,$E40/H$13,$E40*(1+(1/H$13))) -> 0 | I40: =IF($N40=TRUE,$E40/I$13,$E40*(1+(1/I$13))) -> 0 | J40: =IF($N40=TRUE,$E40/J$13,$E40*(1+(1/J$13))) -> 0 | K40: =IF($N40=TRUE,$E40/K$13,$E40*(1+(1/K$13))) -> 0 | L40: =IF($N40=TRUE,$E40/L$13,$E40*(1+(1/L$13))) -> 0 | M40: =IF($N40=TRUE,$E40/M$13,$E40*(1+(1/M$13))) -> 0 | N40: FALSE | S40: =G13 -> 25 | T40: =G63 -> 0
E41: =C41*D41 -> 0 | F41: =IF($N41=TRUE,$E41/F$13,$E41*(1+(1/F$13))) -> 0 | G41: =IF($N41=TRUE,$E41/G$13,$E41*(1+(1/G$13))) -> 0 | H41: =IF($N41=TRUE,$E41/H$13,$E41*(1+(1/H$13))) -> 0 | I41: =IF($N41=TRUE,$E41/I$13,$E41*(1+(1/I$13))) -> 0 | J41: =IF($N41=TRUE,$E41/J$13,$E41*(1+(1/J$13))) -> 0 | K41: =IF($N41=TRUE,$E41/K$13,$E41*(1+(1/K$13))) -> 0 | L41: =IF($N41=TRUE,$E41/L$13,$E41*(1+(1/L$13))) -> 0 | M41: =IF($N41=TRUE,$E41/M$13,$E41*(1+(1/M$13))) -> 0 | N41: FALSE | S41: =F13 -> 10 | T41: =F63 -> 0
E42: =C42*D42 -> 0 | F42: =IF($N42=TRUE,$E42/F$13,$E42*(1+(1/F$13))) -> 0 | G42: =IF($N42=TRUE,$E42/G$13,$E42*(1+(1/G$13))) -> 0 | H42: =IF($N42=TRUE,$E42/H$13,$E42*(1+(1/H$13))) -> 0 | I42: =IF($N42=TRUE,$E42/I$13,$E42*(1+(1/I$13))) -> 0 | J42: =IF($N42=TRUE,$E42/J$13,$E42*(1+(1/J$13))) -> 0 | K42: =IF($N42=TRUE,$E42/K$13,$E42*(1+(1/K$13))) -> 0 | L42: =IF($N42=TRUE,$E42/L$13,$E42*(1+(1/L$13))) -> 0 | M42: =IF($N42=TRUE,$E42/M$13,$E42*(1+(1/M$13))) -> 0 | N42: FALSE
E43: =C43*D43 -> 0 | F43: =IF($N43=TRUE,$E43/F$13,$E43*(1+(1/F$13))) -> 0 | G43: =IF($N43=TRUE,$E43/G$13,$E43*(1+(1/G$13))) -> 0 | H43: =IF($N43=TRUE,$E43/H$13,$E43*(1+(1/H$13))) -> 0 | I43: =IF($N43=TRUE,$E43/I$13,$E43*(1+(1/I$13))) -> 0 | J43: =IF($N43=TRUE,$E43/J$13,$E43*(1+(1/J$13))) -> 0 | K43: =IF($N43=TRUE,$E43/K$13,$E43*(1+(1/K$13))) -> 0 | L43: =IF($N43=TRUE,$E43/L$13,$E43*(1+(1/L$13))) -> 0 | M43: =IF($N43=TRUE,$E43/M$13,$E43*(1+(1/M$13))) -> 0 | N43: FALSE
E44: =C44*D44 -> 0 | F44: =IF($N44=TRUE,$E44/F$13,$E44*(1+(1/F$13))) -> 0 | G44: =IF($N44=TRUE,$E44/G$13,$E44*(1+(1/G$13))) -> 0 | H44: =IF($N44=TRUE,$E44/H$13,$E44*(1+(1/H$13))) -> 0 | I44: =IF($N44=TRUE,$E44/I$13,$E44*(1+(1/I$13))) -> 0 | J44: =IF($N44=TRUE,$E44/J$13,$E44*(1+(1/J$13))) -> 0 | K44: =IF($N44=TRUE,$E44/K$13,$E44*(1+(1/K$13))) -> 0 | L44: =IF($N44=TRUE,$E44/L$13,$E44*(1+(1/L$13))) -> 0 | M44: =IF($N44=TRUE,$E44/M$13,$E44*(1+(1/M$13))) -> 0 | N44: FALSE
A45: PROCESSES/COMPONENTS | D45: SETUP $ | E45: RUN$ EA.
F46: =($D46/F$13)+$E46 -> 0 | G46: =($D46/G$13)+$E46 -> 0 | H46: =($D46/H$13)+$E46 -> 0 | I46: =($D46/I$13)+$E46 -> 0 | J46: =($D46/J$13)+$E46 -> 0 | K46: =($D46/K$13)+$E46 -> 0 | L46: =($D46/L$13)+$E46 -> 0 | M46: =($D46/M$13)+$E46 -> 0
...

Sheet Subassy 3
A2: CUSTOMER: | F2: Comments:
A3: P/N: | B3: 3 | D3: NSN #:
A4: REV: | D4: SOL #:
A5: QUOTE LOG No.: | D5: RFQ #:
A6: QTY: | B6: =F13&", "&G13&", "&H13&", "&I13&", "&J13&", "&K13&", "&L13&", "&M13 -> 10, 25, 50, 75, 100, 250, 500, 1000
A7: DATE:
A8: ESTIMATOR:
A11: MANUFACTURING OPERATIONS | F11: COST ESTIMATED QUANTITIES | N11: NRE/SET-UP
B13: SET-UP TIME | C13: RUN TIME | E13: LABOR RATE | F13: ='Top Assy'!F13 -> 10 | G13: ='Top Assy'!G13 -> 25 | H13: ='Top Assy'!H13 -> 50 | I13: ='Top Assy'!I13 -> 75 | J13: ='Top Assy'!J13 -> 100 | K13: ='Top Assy'!K13 -> 250 | L13: ='Top Assy'!L13 -> 500 | M13: ='Top Assy'!M13 -> 1000 | N13: 1
A14: Program | E14: 0 | N14: =(($B14/N$13*$E14)+($C14*$E14)) -> 0
A15: Fixtures | E15: 0 | N15: =(($B15/N$13*$E15)+($C15*$E15)) -> 0
A16: Mill/Turn | E16: 0 | F16: =(($B16/F$13*$E16)+($C16*$E16)) -> 0 | G16: =(($B16/G$13*$E16)+($C16*$E16)) -> 0 | H16: =(($B16/H$13*$E16)+($C16*$E16)) -> 0 | I16: =(($B16/I$13*$E16)+($C16*$E16)) -> 0 | J16: =(($B16/J$13*$E16)+($C16*$E16)) -> 0 | K16: =(($B16/K$13*$E16)+($C16*$E16)) -> 0 | L16: =(($B16/L$13*$E16)+($C16*$E16)) -> 0 | M16: =(($B16/M$13*$E16)+($C16*$E16)) -> 0
A17: Metals - Mills | E17: 0 | F17: =(($B17/F$13*$E17)+($C17*$E17)) -> 0 | G17: =(($B17/G$13*$E17)+($C17*$E17)) -> 0 | H17: =(($B17/H$13*$E17)+($C17*$E17)) -> 0 | I17: =(($B17/I$13*$E17)+($C17*$E17)) -> 0 | J17: =(($B17/J$13*$E17)+($C17*$E17)) -> 0 | K17: =(($B17/K$13*$E17)+($C17*$E17)) -> 0 | L17: =(($B17/L$13*$E17)+($C17*$E17)) -> 0 | M17: =(($B17/M$13*$E17)+($C17*$E17)) -> 0
A18: Metals - Lathe | E18: 0 | F18: =(($B18/F$13*$E18)+($C18*$E18)) -> 0 | G18: =(($B18/G$13*$E18)+($C18*$E18)) -> 0 | H18: =(($B18/H$13*$E18)+($C18*$E18)) -> 0 | I18: =(($B18/I$13*$E18)+($C18*$E18)) -> 0 | J18: =(($B18/J$13*$E18)+($C18*$E18)) -> 0 | K18: =(($B18/K$13*$E18)+($C18*$E18)) -> 0 | L18: =(($B18/L$13*$E18)+($C18*$E18)) -> 0 | M18: =(($B18/M$13*$E18)+($C18*$E18)) -> 0
A19: Rubber Mold | E19: 0 | F19: =(($B19/F$13*$E19)+($C19*$E19)) -> 0 | G19: =(($B19/G$13*$E19)+($C19*$E19)) -> 0 | H19: =(($B19/H$13*$E19)+($C19*$E19)) -> 0 | I19: =(($B19/I$13*$E19)+($C19*$E19)) -> 0 | J19: =(($B19/J$13*$E19)+($C19*$E19)) -> 0 | K19: =(($B19/K$13*$E19)+($C19*$E19)) -> 0 | L19: =(($B19/L$13*$E19)+($C19*$E19)) -> 0 | M19: =(($B19/M$13*$E19)+($C19*$E19)) -> 0
A20: Plastic Injection Mold | E20: 0 | F20: =(($B20/F$13*$E20)+($C20*$E20)) -> 0 | G20: =(($B20/G$13*$E20)+($C20*$E20)) -> 0 | H20: =(($B20/H$13*$E20)+($C20*$E20)) -> 0 | I20: =(($B20/I$13*$E20)+($C20*$E20)) -> 0 | J20: =(($B20/J$13*$E20)+($C20*$E20)) -> 0 | K20: =(($B20/K$13*$E20)+($C20*$E20)) -> 0 | L20: =(($B20/L$13*$E20)+($C20*$E20)) -> 0 | M20: =(($B20/M$13*$E20)+($C20*$E20)) -> 0
A21: Plastic Compression Mold | E21: 0 | F21: =(($B21/F$13*$E21)+($C21*$E21)) -> 0 | G21: =(($B21/G$13*$E21)+($C21*$E21)) -> 0 | H21: =(($B21/H$13*$E21)+($C21*$E21)) -> 0 | I21: =(($B21/I$13*$E21)+($C21*$E21)) -> 0 | J21: =(($B21/J$13*$E21)+($C21*$E21)) -> 0 | K21: =(($B21/K$13*$E21)+($C21*$E21)) -> 0 | L21: =(($B21/L$13*$E21)+($C21*$E21)) -> 0 | M21: =(($B21/M$13*$E21)+($C21*$E21)) -> 0
A22: Waterjet - Setup | E22: 0 | F22: =(($B22/F$13*$E22)+($C22*$E22)) -> 0 | G22: =(($B22/G$13*$E22)+($C22*$E22)) -> 0 | H22: =(($B22/H$13*$E22)+($C22*$E22)) -> 0 | I22: =(($B22/I$13*$E22)+($C22*$E22)) -> 0 | J22: =(($B22/J$13*$E22)+($C22*$E22)) -> 0 | K22: =(($B22/K$13*$E22)+($C22*$E22)) -> 0 | L22: =(($B22/L$13*$E22)+($C22*$E22)) -> 0 | M22: =(($B22/M$13*$E22)+($C22*$E22)) -> 0
A23: Waterjet - Operator | E23: 0 | F23: =(($B23/F$13*$E23)+($C23*$E23)) -> 0 | G23: =(($B23/G$13*$E23)+($C23*$E23)) -> 0 | H23: =(($B23/H$13*$E23)+($C23*$E23)) -> 0 | I23: =(($B23/I$13*$E23)+($C23*$E23)) -> 0 | J23: =(($B23/J$13*$E23)+($C23*$E23)) -> 0 | K23: =(($B23/K$13*$E23)+($C23*$E23)) -> 0 | L23: =(($B23/L$13*$E23)+($C23*$E23)) -> 0 | M23: =(($B23/M$13*$E23)+($C23*$E23)) -> 0
A24: Assembly, Die Punch, Deburr | E24: 0 | F24: =(($B24/F$13*$E24)+($C24*$E24)) -> 0 | G24: =(($B24/G$13*$E24)+($C24*$E24)) -> 0 | H24: =(($B24/H$13*$E24)+($C24*$E24)) -> 0 | I24: =(($B24/I$13*$E24)+($C24*$E24)) -> 0 | J24: =(($B24/J$13*$E24)+($C24*$E24)) -> 0 | K24: =(($B24/K$13*$E24)+($C24*$E24)) -> 0 | L24: =(($B24/L$13*$E24)+($C24*$E24)) -> 0 | M24: =(($B24/M$13*$E24)+($C24*$E24)) -> 0
A25: Quality Inspection | E25: 0 | F25: =(($B25/F$13*$E25)+($C25*$E25)) -> 0 | G25: =(($B25/G$13*$E25)+($C25*$E25)) -> 0 | H25: =(($B25/H$13*$E25)+($C25*$E25)) -> 0 | I25: =(($B25/I$13*$E25)+($C25*$E25)) -> 0 | J25: =(($B25/J$13*$E25)+($C25*$E25)) -> 0 | K25: =(($B25/K$13*$E25)+($C25*$E25)) -> 0 | L25: =(($B25/L$13*$E25)+($C25*$E25)) -> 0 | M25: =(($B25/M$13*$E25)+($C25*$E25)) -> 0
C26: Labor | E26: Basic LABOR | F26: =SUM(F16:F25) -> 0 | G26: =SUM(G16:G25) -> 0 | H26: =SUM(H16:H25) -> 0 | I26: =SUM(I16:I25) -> 0 | J26: =SUM(J16:J25) -> 0 | K26: =SUM(K16:K25) -> 0 | L26: =SUM(L16:L25) -> 0 | M26: =SUM(M16:M25) -> 0 | N26: =SUM(N14:N25) -> 0
B27: T. setup | C27: T.RUN | E27: hrs | F27: =(($B$28/F13)+$C$28)/60 -> 0 | G27: =(($B$28/G13)+$C$28)/60 -> 0 | H27: =(($B$28/H13)+$C$28)/60 -> 0 | I27: =(($B$28/I13)+$C$28)/60 -> 0 | J27: =(($B$28/J13)+$C$28)/60 -> 0 | K27: =(($B$28/K13)+$C$28)/60 -> 0 | L27: =(($B$28/L13)+$C$28)/60 -> 0 | M27: =(($B$28/M13)+$C$28)/60 -> 0
B28: =SUM(B16:B25) -> 0 | C28: =SUM(C16:C25) -> 0 | D28: 0 | E28: BURDEN | F28: =F26*$D$28 -> 0 | G28: =G26*$D$28 -> 0 | H28: =H26*$D$28 -> 0 | I28: =I26*$D$28 -> 0 | J28: =J26*$D$28 -> 0 | K28: =K26*$D$28 -> 0 | L28: =L26*$D$28 -> 0 | M28: =M26*$D$28 -> 0
E30: Total | F30: =F26+F28 -> 0 | G30: =G26+G28 -> 0 | H30: =H26+H28 -> 0 | I30: =I26+I28 -> 0 | J30: =J26+J28 -> 0 | K30: =K26+K28 -> 0 | L30: =L26+L28 -> 0 | M30: =M26+M28 -> 0 | N30: =N26 -> 0
A32: RAW MATERIALS & HARDWARE | B32: Matl UoM | C32: PARTS QTY | D32: UNIT PRICE | E32: MAT'l BURDEN | F32: ="Qty: "& F13 -> Qty: 10 | G32: ="Qty: "& G13 -> Qty: 25 | H32: ="Qty: "& H13 -> Qty: 50 | I32: ="Qty: "& I13 -> Qty: 75 | J32: ="Qty: "& J13 -> Qty: 100 | K32: ="Qty: "& K13 -> Qty: 250 | L32: ="Qty: "& L13 -> Qty: 500 | M32: ="Qty: "& M13 -> Qty: 1000 | N32: Amortize/ Min Buy
E33: =C33*D33 -> 0 | F33: =IF($N33=TRUE,$E33/F$13,$E33*(1+(1/F$13))) -> 0 | G33: =IF($N33=TRUE,$E33/G$13,$E33*(1+(1/G$13))) -> 0 | H33: =IF($N33=TRUE,$E33/H$13,$E33*(1+(1/H$13))) -> 0 | I33: =IF($N33=TRUE,$E33/I$13,$E33*(1+(1/I$13))) -> 0 | J33: =IF($N33=TRUE,$E33/J$13,$E33*(1+(1/J$13))) -> 0 | K33: =IF($N33=TRUE,$E33/K$13,$E33*(1+(1/K$13))) -> 0 | L33: =IF($N33=TRUE,$E33/L$13,$E33*(1+(1/L$13))) -> 0 | M33: =IF($N33=TRUE,$E33/M$13,$E33*(1+(1/M$13))) -> 0 | N33: FALSE
E34: =C34*D34 -> 0 | F34: =IF($N34=TRUE,$E34/F$13,$E34*(1+(1/F$13))) -> 0 | G34: =IF($N34=TRUE,$E34/G$13,$E34*(1+(1/G$13))) -> 0 | H34: =IF($N34=TRUE,$E34/H$13,$E34*(1+(1/H$13))) -> 0 | I34: =IF($N34=TRUE,$E34/I$13,$E34*(1+(1/I$13))) -> 0 | J34: =IF($N34=TRUE,$E34/J$13,$E34*(1+(1/J$13))) -> 0 | K34: =IF($N34=TRUE,$E34/K$13,$E34*(1+(1/K$13))) -> 0 | L34: =IF($N34=TRUE,$E34/L$13,$E34*(1+(1/L$13))) -> 0 | M34: =IF($N34=TRUE,$E34/M$13,$E34*(1+(1/M$13))) -> 0 | N34: FALSE
E35: =C35*D35 -> 0 | F35: =IF($N35=TRUE,$E35/F$13,$E35*(1+(1/F$13))) -> 0 | G35: =IF($N35=TRUE,$E35/G$13,$E35*(1+(1/G$13))) -> 0 | H35: =IF($N35=TRUE,$E35/H$13,$E35*(1+(1/H$13))) -> 0 | I35: =IF($N35=TRUE,$E35/I$13,$E35*(1+(1/I$13))) -> 0 | J35: =IF($N35=TRUE,$E35/J$13,$E35*(1+(1/J$13))) -> 0 | K35: =IF($N35=TRUE,$E35/K$13,$E35*(1+(1/K$13))) -> 0 | L35: =IF($N35=TRUE,$E35/L$13,$E35*(1+(1/L$13))) -> 0 | M35: =IF($N35=TRUE,$E35/M$13,$E35*(1+(1/M$13))) -> 0 | N35: FALSE | S35: QTY | T35: Total
E36: =C36*D36 -> 0 | F36: =IF($N36=TRUE,$E36/F$13,$E36*(1+(1/F$13))) -> 0 | G36: =IF($N36=TRUE,$E36/G$13,$E36*(1+(1/G$13))) -> 0 | H36: =IF($N36=TRUE,$E36/H$13,$E36*(1+(1/H$13))) -> 0 | I36: =IF($N36=TRUE,$E36/I$13,$E36*(1+(1/I$13))) -> 0 | J36: =IF($N36=TRUE,$E36/J$13,$E36*(1+(1/J$13))) -> 0 | K36: =IF($N36=TRUE,$E36/K$13,$E36*(1+(1/K$13))) -> 0 | L36: =IF($N36=TRUE,$E36/L$13,$E36*(1+(1/L$13))) -> 0 | M36: =IF($N36=TRUE,$E36/M$13,$E36*(1+(1/M$13))) -> 0 | N36: FALSE | S36: =M13 -> 1000 | T36: =M63 -> 0
E37: =C37*D37 -> 0 | F37: =IF($N37=TRUE,$E37/F$13,$E37*(1+(1/F$13))) -> 0 | G37: =IF($N37=TRUE,$E37/G$13,$E37*(1+(1/G$13))) -> 0 | H37: =IF($N37=TRUE,$E37/H$13,$E37*(1+(1/H$13))) -> 0 | I37: =IF($N37=TRUE,$E37/I$13,$E37*(1+(1/I$13))) -> 0 | J37: =IF($N37=TRUE,$E37/J$13,$E37*(1+(1/J$13))) -> 0 | K37: =IF($N37=TRUE,$E37/K$13,$E37*(1+(1/K$13))) -> 0 | L37: =IF($N37=TRUE,$E37/L$13,$E37*(1+(1/L$13))) -> 0 | M37: =IF($N37=TRUE,$E37/M$13,$E37*(1+(1/M$13))) -> 0 | N37: FALSE | S37: =L13 -> 500 | T37: =L63 -> 0
E38: =C38*D38 -> 0 | F38: =IF($N38=TRUE,$E38/F$13,$E38*(1+(1/F$13))) -> 0 | G38: =IF($N38=TRUE,$E38/G$13,$E38*(1+(1/G$13))) -> 0 | H38: =IF($N38=TRUE,$E38/H$13,$E38*(1+(1/H$13))) -> 0 | I38: =IF($N38=TRUE,$E38/I$13,$E38*(1+(1/I$13))) -> 0 | J38: =IF($N38=TRUE,$E38/J$13,$E38*(1+(1/J$13))) -> 0 | K38: =IF($N38=TRUE,$E38/K$13,$E38*(1+(1/K$13))) -> 0 | L38: =IF($N38=TRUE,$E38/L$13,$E38*(1+(1/L$13))) -> 0 | M38: =IF($N38=TRUE,$E38/M$13,$E38*(1+(1/M$13))) -> 0 | N38: FALSE | S38: =K13 -> 250 | T38: =K63 -> 0
E39: =C39*D39 -> 0 | F39: =IF($N39=TRUE,$E39/F$13,$E39*(1+(1/F$13))) -> 0 | G39: =IF($N39=TRUE,$E39/G$13,$E39*(1+(1/G$13))) -> 0 | H39: =IF($N39=TRUE,$E39/H$13,$E39*(1+(1/H$13))) -> 0 | I39: =IF($N39=TRUE,$E39/I$13,$E39*(1+(1/I$13))) -> 0 | J39: =IF($N39=TRUE,$E39/J$13,$E39*(1+(1/J$13))) -> 0 | K39: =IF($N39=TRUE,$E39/K$13,$E39*(1+(1/K$13))) -> 0 | L39: =IF($N39=TRUE,$E39/L$13,$E39*(1+(1/L$13))) -> 0 | M39: =IF($N39=TRUE,$E39/M$13,$E39*(1+(1/M$13))) -> 0 | N39: FALSE | S39: =H13 -> 50 | T39: =H63 -> 0
E40: =C40*D40 -> 0 | F40: =IF($N40=TRUE,$E40/F$13,$E40*(1+(1/F$13))) -> 0 | G40: =IF($N40=TRUE,$E40/G$13,$E40*(1+(1/G$13))) -> 0 | H40: =IF($N40=TRUE,$E40/H$13,$E40*(1+(1/H$13))) -> 0 | I40: =IF($N40=TRUE,$E40/I$13,$E40*(1+(1/I$13))) -> 0 | J40: =IF($N40=TRUE,$E40/J$13,$E40*(1+(1/J$13))) -> 0 | K40: =IF($N40=TRUE,$E40/K$13,$E40*(1+(1/K$13))) -> 0 | L40: =IF($N40=TRUE,$E40/L$13,$E40*(1+(1/L$13))) -> 0 | M40: =IF($N40=TRUE,$E40/M$13,$E40*(1+(1/M$13))) -> 0 | N40: FALSE | S40: =G13 -> 25 | T40: =G63 -> 0
E41: =C41*D41 -> 0 | F41: =IF($N41=TRUE,$E41/F$13,$E41*(1+(1/F$13))) -> 0 | G41: =IF($N41=TRUE,$E41/G$13,$E41*(1+(1/G$13))) -> 0 | H41: =IF($N41=TRUE,$E41/H$13,$E41*(1+(1/H$13))) -> 0 | I41: =IF($N41=TRUE,$E41/I$13,$E41*(1+(1/I$13))) -> 0 | J41: =IF($N41=TRUE,$E41/J$13,$E41*(1+(1/J$13))) -> 0 | K41: =IF($N41=TRUE,$E41/K$13,$E41*(1+(1/K$13))) -> 0 | L41: =IF($N41=TRUE,$E41/L$13,$E41*(1+(1/L$13))) -> 0 | M41: =IF($N41=TRUE,$E41/M$13,$E41*(1+(1/M$13))) -> 0 | N41: FALSE | S41: =F13 -> 10 | T41: =F63 -> 0
E42: =C42*D42 -> 0 | F42: =IF($N42=TRUE,$E42/F$13,$E42*(1+(1/F$13))) -> 0 | G42: =IF($N42=TRUE,$E42/G$13,$E42*(1+(1/G$13))) -> 0 | H42: =IF($N42=TRUE,$E42/H$13,$E42*(1+(1/H$13))) -> 0 | I42: =IF($N42=TRUE,$E42/I$13,$E42*(1+(1/I$13))) -> 0 | J42: =IF($N42=TRUE,$E42/J$13,$E42*(1+(1/J$13))) -> 0 | K42: =IF($N42=TRUE,$E42/K$13,$E42*(1+(1/K$13))) -> 0 | L42: =IF($N42=TRUE,$E42/L$13,$E42*(1+(1/L$13))) -> 0 | M42: =IF($N42=TRUE,$E42/M$13,$E42*(1+(1/M$13))) -> 0 | N42: FALSE
E43: =C43*D43 -> 0 | F43: =IF($N43=TRUE,$E43/F$13,$E43*(1+(1/F$13))) -> 0 | G43: =IF($N43=TRUE,$E43/G$13,$E43*(1+(1/G$13))) -> 0 | H43: =IF($N43=TRUE,$E43/H$13,$E43*(1+(1/H$13))) -> 0 | I43: =IF($N43=TRUE,$E43/I$13,$E43*(1+(1/I$13))) -> 0 | J43: =IF($N43=TRUE,$E43/J$13,$E43*(1+(1/J$13))) -> 0 | K43: =IF($N43=TRUE,$E43/K$13,$E43*(1+(1/K$13))) -> 0 | L43: =IF($N43=TRUE,$E43/L$13,$E43*(1+(1/L$13))) -> 0 | M43: =IF($N43=TRUE,$E43/M$13,$E43*(1+(1/M$13))) -> 0 | N43: FALSE
E44: =C44*D44 -> 0 | F44: =IF($N44=TRUE,$E44/F$13,$E44*(1+(1/F$13))) -> 0 | G44: =IF($N44=TRUE,$E44/G$13,$E44*(1+(1/G$13))) -> 0 | H44: =IF($N44=TRUE,$E44/H$13,$E44*(1+(1/H$13))) -> 0 | I44: =IF($N44=TRUE,$E44/I$13,$E44*(1+(1/I$13))) -> 0 | J44: =IF($N44=TRUE,$E44/J$13,$E44*(1+(1/J$13))) -> 0 | K44: =IF($N44=TRUE,$E44/K$13,$E44*(1+(1/K$13))) -> 0 | L44: =IF($N44=TRUE,$E44/L$13,$E44*(1+(1/L$13))) -> 0 | M44: =IF($N44=TRUE,$E44/M$13,$E44*(1+(1/M$13))) -> 0 | N44: FALSE
A45: PROCESSES/COMPONENTS | D45: SETUP $ | E45: RUN$ EA.
F46: =($D46/F$13)+$E46 -> 0 | G46: =($D46/G$13)+$E46 -> 0 | H46: =($D46/H$13)+$E46 -> 0 | I46: =($D46/I$13)+$E46 -> 0 | J46: =($D46/J$13)+$E46 -> 0 | K46: =($D46/K$13)+$E46 -> 0 | L46: =($D46/L$13)+$E46 -> 0 | M46: =($D46/M$13)+$E46 -> 0
...

Sheet Subassy 4
A2: CUSTOMER: | F2: Comments:
A3: P/N: | B3: 4 | D3: NSN #:
A4: REV: | D4: SOL #:
A5: QUOTE LOG No.: | D5: RFQ #:
A6: QTY: | B6: =F13&", "&G13&", "&H13&", "&I13&", "&J13&", "&K13&", "&L13&", "&M13 -> 10, 25, 50, 75, 100, 250, 500, 1000
A7: DATE:
A8: ESTIMATOR:
A11: MANUFACTURING OPERATIONS | F11: COST ESTIMATED QUANTITIES | N11: NRE/SET-UP
B13: SET-UP TIME | C13: RUN TIME | E13: LABOR RATE | F13: ='Top Assy'!F13 -> 10 | G13: ='Top Assy'!G13 -> 25 | H13: ='Top Assy'!H13 -> 50 | I13: ='Top Assy'!I13 -> 75 | J13: ='Top Assy'!J13 -> 100 | K13: ='Top Assy'!K13 -> 250 | L13: ='Top Assy'!L13 -> 500 | M13: ='Top Assy'!M13 -> 1000 | N13: 1
A14: Program | E14: 0 | N14: =(($B14/N$13*$E14)+($C14*$E14)) -> 0
A15: Fixtures | E15: 0 | N15: =(($B15/N$13*$E15)+($C15*$E15)) -> 0
A16: Mill/Turn | E16: 0 | F16: =(($B16/F$13*$E16)+($C16*$E16)) -> 0 | G16: =(($B16/G$13*$E16)+($C16*$E16)) -> 0 | H16: =(($B16/H$13*$E16)+($C16*$E16)) -> 0 | I16: =(($B16/I$13*$E16)+($C16*$E16)) -> 0 | J16: =(($B16/J$13*$E16)+($C16*$E16)) -> 0 | K16: =(($B16/K$13*$E16)+($C16*$E16)) -> 0 | L16: =(($B16/L$13*$E16)+($C16*$E16)) -> 0 | M16: =(($B16/M$13*$E16)+($C16*$E16)) -> 0
A17: Metals - Mills | E17: 0 | F17: =(($B17/F$13*$E17)+($C17*$E17)) -> 0 | G17: =(($B17/G$13*$E17)+($C17*$E17)) -> 0 | H17: =(($B17/H$13*$E17)+($C17*$E17)) -> 0 | I17: =(($B17/I$13*$E17)+($C17*$E17)) -> 0 | J17: =(($B17/J$13*$E17)+($C17*$E17)) -> 0 | K17: =(($B17/K$13*$E17)+($C17*$E17)) -> 0 | L17: =(($B17/L$13*$E17)+($C17*$E17)) -> 0 | M17: =(($B17/M$13*$E17)+($C17*$E17)) -> 0
A18: Metals - Lathe | E18: 0 | F18: =(($B18/F$13*$E18)+($C18*$E18)) -> 0 | G18: =(($B18/G$13*$E18)+($C18*$E18)) -> 0 | H18: =(($B18/H$13*$E18)+($C18*$E18)) -> 0 | I18: =(($B18/I$13*$E18)+($C18*$E18)) -> 0 | J18: =(($B18/J$13*$E18)+($C18*$E18)) -> 0 | K18: =(($B18/K$13*$E18)+($C18*$E18)) -> 0 | L18: =(($B18/L$13*$E18)+($C18*$E18)) -> 0 | M18: =(($B18/M$13*$E18)+($C18*$E18)) -> 0
A19: Rubber Mold | E19: 0 | F19: =(($B19/F$13*$E19)+($C19*$E19)) -> 0 | G19: =(($B19/G$13*$E19)+($C19*$E19)) -> 0 | H19: =(($B19/H$13*$E19)+($C19*$E19)) -> 0 | I19: =(($B19/I$13*$E19)+($C19*$E19)) -> 0 | J19: =(($B19/J$13*$E19)+($C19*$E19)) -> 0 | K19: =(($B19/K$13*$E19)+($C19*$E19)) -> 0 | L19: =(($B19/L$13*$E19)+($C19*$E19)) -> 0 | M19: =(($B19/M$13*$E19)+($C19*$E19)) -> 0
A20: Plastic Injection Mold | E20: 0 | F20: =(($B20/F$13*$E20)+($C20*$E20)) -> 0 | G20: =(($B20/G$13*$E20)+($C20*$E20)) -> 0 | H20: =(($B20/H$13*$E20)+($C20*$E20)) -> 0 | I20: =(($B20/I$13*$E20)+($C20*$E20)) -> 0 | J20: =(($B20/J$13*$E20)+($C20*$E20)) -> 0 | K20: =(($B20/K$13*$E20)+($C20*$E20)) -> 0 | L20: =(($B20/L$13*$E20)+($C20*$E20)) -> 0 | M20: =(($B20/M$13*$E20)+($C20*$E20)) -> 0
A21: Plastic Compression Mold | E21: 0 | F21: =(($B21/F$13*$E21)+($C21*$E21)) -> 0 | G21: =(($B21/G$13*$E21)+($C21*$E21)) -> 0 | H21: =(($B21/H$13*$E21)+($C21*$E21)) -> 0 | I21: =(($B21/I$13*$E21)+($C21*$E21)) -> 0 | J21: =(($B21/J$13*$E21)+($C21*$E21)) -> 0 | K21: =(($B21/K$13*$E21)+($C21*$E21)) -> 0 | L21: =(($B21/L$13*$E21)+($C21*$E21)) -> 0 | M21: =(($B21/M$13*$E21)+($C21*$E21)) -> 0
A22: Waterjet - Setup | E22: 0 | F22: =(($B22/F$13*$E22)+($C22*$E22)) -> 0 | G22: =(($B22/G$13*$E22)+($C22*$E22)) -> 0 | H22: =(($B22/H$13*$E22)+($C22*$E22)) -> 0 | I22: =(($B22/I$13*$E22)+($C22*$E22)) -> 0 | J22: =(($B22/J$13*$E22)+($C22*$E22)) -> 0 | K22: =(($B22/K$13*$E22)+($C22*$E22)) -> 0 | L22: =(($B22/L$13*$E22)+($C22*$E22)) -> 0 | M22: =(($B22/M$13*$E22)+($C22*$E22)) -> 0
A23: Waterjet - Operator | E23: 0 | F23: =(($B23/F$13*$E23)+($C23*$E23)) -> 0 | G23: =(($B23/G$13*$E23)+($C23*$E23)) -> 0 | H23: =(($B23/H$13*$E23)+($C23*$E23)) -> 0 | I23: =(($B23/I$13*$E23)+($C23*$E23)) -> 0 | J23: =(($B23/J$13*$E23)+($C23*$E23)) -> 0 | K23: =(($B23/K$13*$E23)+($C23*$E23)) -> 0 | L23: =(($B23/L$13*$E23)+($C23*$E23)) -> 0 | M23: =(($B23/M$13*$E23)+($C23*$E23)) -> 0
A24: Assembly, Die Punch, Deburr | E24: 0 | F24: =(($B24/F$13*$E24)+($C24*$E24)) -> 0 | G24: =(($B24/G$13*$E24)+($C24*$E24)) -> 0 | H24: =(($B24/H$13*$E24)+($C24*$E24)) -> 0 | I24: =(($B24/I$13*$E24)+($C24*$E24)) -> 0 | J24: =(($B24/J$13*$E24)+($C24*$E24)) -> 0 | K24: =(($B24/K$13*$E24)+($C24*$E24)) -> 0 | L24: =(($B24/L$13*$E24)+($C24*$E24)) -> 0 | M24: =(($B24/M$13*$E24)+($C24*$E24)) -> 0
A25: Quality Inspection | E25: 0 | F25: =(($B25/F$13*$E25)+($C25*$E25)) -> 0 | G25: =(($B25/G$13*$E25)+($C25*$E25)) -> 0 | H25: =(($B25/H$13*$E25)+($C25*$E25)) -> 0 | I25: =(($B25/I$13*$E25)+($C25*$E25)) -> 0 | J25: =(($B25/J$13*$E25)+($C25*$E25)) -> 0 | K25: =(($B25/K$13*$E25)+($C25*$E25)) -> 0 | L25: =(($B25/L$13*$E25)+($C25*$E25)) -> 0 | M25: =(($B25/M$13*$E25)+($C25*$E25)) -> 0
C26: Labor | E26: Basic LABOR | F26: =SUM(F16:F25) -> 0 | G26: =SUM(G16:G25) -> 0 | H26: =SUM(H16:H25) -> 0 | I26: =SUM(I16:I25) -> 0 | J26: =SUM(J16:J25) -> 0 | K26: =SUM(K16:K25) -> 0 | L26: =SUM(L16:L25) -> 0 | M26: =SUM(M16:M25) -> 0 | N26: =SUM(N14:N25) -> 0
B27: T. setup | C27: T.RUN | E27: hrs | F27: =(($B$28/F13)+$C$28)/60 -> 0 | G27: =(($B$28/G13)+$C$28)/60 -> 0 | H27: =(($B$28/H13)+$C$28)/60 -> 0 | I27: =(($B$28/I13)+$C$28)/60 -> 0 | J27: =(($B$28/J13)+$C$28)/60 -> 0 | K27: =(($B$28/K13)+$C$28)/60 -> 0 | L27: =(($B$28/L13)+$C$28)/60 -> 0 | M27: =(($B$28/M13)+$C$28)/60 -> 0
B28: =SUM(B16:B25) -> 0 | C28: =SUM(C16:C25) -> 0 | D28: 0 | E28: BURDEN | F28: =F26*$D$28 -> 0 | G28: =G26*$D$28 -> 0 | H28: =H26*$D$28 -> 0 | I28: =I26*$D$28 -> 0 | J28: =J26*$D$28 -> 0 | K28: =K26*$D$28 -> 0 | L28: =L26*$D$28 -> 0 | M28: =M26*$D$28 -> 0
E30: Total | F30: =F26+F28 -> 0 | G30: =G26+G28 -> 0 | H30: =H26+H28 -> 0 | I30: =I26+I28 -> 0 | J30: =J26+J28 -> 0 | K30: =K26+K28 -> 0 | L30: =L26+L28 -> 0 | M30: =M26+M28 -> 0 | N30: =N26 -> 0
A32: RAW MATERIALS & HARDWARE | B32: Matl UoM | C32: PARTS QTY | D32: UNIT PRICE | E32: MAT'l BURDEN | F32: ="Qty: "& F13 -> Qty: 10 | G32: ="Qty: "& G13 -> Qty: 25 | H32: ="Qty: "& H13 -> Qty: 50 | I32: ="Qty: "& I13 -> Qty: 75 | J32: ="Qty: "& J13 -> Qty: 100 | K32: ="Qty: "& K13 -> Qty: 250 | L32: ="Qty: "& L13 -> Qty: 500 | M32: ="Qty: "& M13 -> Qty: 1000 | N32: Amortize/ Min Buy
E33: =C33*D33 -> 0 | F33: =IF($N33=TRUE,$E33/F$13,$E33*(1+(1/F$13))) -> 0 | G33: =IF($N33=TRUE,$E33/G$13,$E33*(1+(1/G$13))) -> 0 | H33: =IF($N33=TRUE,$E33/H$13,$E33*(1+(1/H$13))) -> 0 | I33: =IF($N33=TRUE,$E33/I$13,$E33*(1+(1/I$13))) -> 0 | J33: =IF($N33=TRUE,$E33/J$13,$E33*(1+(1/J$13))) -> 0 | K33: =IF($N33=TRUE,$E33/K$13,$E33*(1+(1/K$13))) -> 0 | L33: =IF($N33=TRUE,$E33/L$13,$E33*(1+(1/L$13))) -> 0 | M33: =IF($N33=TRUE,$E33/M$13,$E33*(1+(1/M$13))) -> 0 | N33: FALSE
E34: =C34*D34 -> 0 | F34: =IF($N34=TRUE,$E34/F$13,$E34*(1+(1/F$13))) -> 0 | G34: =IF($N34=TRUE,$E34/G$13,$E34*(1+(1/G$13))) -> 0 | H34: =IF($N34=TRUE,$E34/H$13,$E34*(1+(1/H$13))) -> 0 | I34: =IF($N34=TRUE,$E34/I$13,$E34*(1+(1/I$13))) -> 0 | J34: =IF($N34=TRUE,$E34/J$13,$E34*(1+(1/J$13))) -> 0 | K34: =IF($N34=TRUE,$E34/K$13,$E34*(1+(1/K$13))) -> 0 | L34: =IF($N34=TRUE,$E34/L$13,$E34*(1+(1/L$13))) -> 0 | M34: =IF($N34=TRUE,$E34/M$13,$E34*(1+(1/M$13))) -> 0 | N34: FALSE
E35: =C35*D35 -> 0 | F35: =IF($N35=TRUE,$E35/F$13,$E35*(1+(1/F$13))) -> 0 | G35: =IF($N35=TRUE,$E35/G$13,$E35*(1+(1/G$13))) -> 0 | H35: =IF($N35=TRUE,$E35/H$13,$E35*(1+(1/H$13))) -> 0 | I35: =IF($N35=TRUE,$E35/I$13,$E35*(1+(1/I$13))) -> 0 | J35: =IF($N35=TRUE,$E35/J$13,$E35*(1+(1/J$13))) -> 0 | K35: =IF($N35=TRUE,$E35/K$13,$E35*(1+(1/K$13))) -> 0 | L35: =IF($N35=TRUE,$E35/L$13,$E35*(1+(1/L$13))) -> 0 | M35: =IF($N35=TRUE,$E35/M$13,$E35*(1+(1/M$13))) -> 0 | N35: FALSE | S35: QTY | T35: Total
E36: =C36*D36 -> 0 | F36: =IF($N36=TRUE,$E36/F$13,$E36*(1+(1/F$13))) -> 0 | G36: =IF($N36=TRUE,$E36/G$13,$E36*(1+(1/G$13))) -> 0 | H36: =IF($N36=TRUE,$E36/H$13,$E36*(1+(1/H$13))) -> 0 | I36: =IF($N36=TRUE,$E36/I$13,$E36*(1+(1/I$13))) -> 0 | J36: =IF($N36=TRUE,$E36/J$13,$E36*(1+(1/J$13))) -> 0 | K36: =IF($N36=TRUE,$E36/K$13,$E36*(1+(1/K$13))) -> 0 | L36: =IF($N36=TRUE,$E36/L$13,$E36*(1+(1/L$13))) -> 0 | M36: =IF($N36=TRUE,$E36/M$13,$E36*(1+(1/M$13))) -> 0 | N36: FALSE | S36: =M13 -> 1000 | T36: =M63 -> 0
E37: =C37*D37 -> 0 | F37: =IF($N37=TRUE,$E37/F$13,$E37*(1+(1/F$13))) -> 0 | G37: =IF($N37=TRUE,$E37/G$13,$E37*(1+(1/G$13))) -> 0 | H37: =IF($N37=TRUE,$E37/H$13,$E37*(1+(1/H$13))) -> 0 | I37: =IF($N37=TRUE,$E37/I$13,$E37*(1+(1/I$13))) -> 0 | J37: =IF($N37=TRUE,$E37/J$13,$E37*(1+(1/J$13))) -> 0 | K37: =IF($N37=TRUE,$E37/K$13,$E37*(1+(1/K$13))) -> 0 | L37: =IF($N37=TRUE,$E37/L$13,$E37*(1+(1/L$13))) -> 0 | M37: =IF($N37=TRUE,$E37/M$13,$E37*(1+(1/M$13))) -> 0 | N37: FALSE | S37: =L13 -> 500 | T37: =L63 -> 0
E38: =C38*D38 -> 0 | F38: =IF($N38=TRUE,$E38/F$13,$E38*(1+(1/F$13))) -> 0 | G38: =IF($N38=TRUE,$E38/G$13,$E38*(1+(1/G$13))) -> 0 | H38: =IF($N38=TRUE,$E38/H$13,$E38*(1+(1/H$13))) -> 0 | I38: =IF($N38=TRUE,$E38/I$13,$E38*(1+(1/I$13))) -> 0 | J38: =IF($N38=TRUE,$E38/J$13,$E38*(1+(1/J$13))) -> 0 | K38: =IF($N38=TRUE,$E38/K$13,$E38*(1+(1/K$13))) -> 0 | L38: =IF($N38=TRUE,$E38/L$13,$E38*(1+(1/L$13))) -> 0 | M38: =IF($N38=TRUE,$E38/M$13,$E38*(1+(1/M$13))) -> 0 | N38: FALSE | S38: =I13 -> 75 | T38: =I63 -> 0
E39: =C39*D39 -> 0 | F39: =IF($N39=TRUE,$E39/F$13,$E39*(1+(1/F$13))) -> 0 | G39: =IF($N39=TRUE,$E39/G$13,$E39*(1+(1/G$13))) -> 0 | H39: =IF($N39=TRUE,$E39/H$13,$E39*(1+(1/H$13))) -> 0 | I39: =IF($N39=TRUE,$E39/I$13,$E39*(1+(1/I$13))) -> 0 | J39: =IF($N39=TRUE,$E39/J$13,$E39*(1+(1/J$13))) -> 0 | K39: =IF($N39=TRUE,$E39/K$13,$E39*(1+(1/K$13))) -> 0 | L39: =IF($N39=TRUE,$E39/L$13,$E39*(1+(1/L$13))) -> 0 | M39: =IF($N39=TRUE,$E39/M$13,$E39*(1+(1/M$13))) -> 0 | N39: FALSE | S39: =H13 -> 50 | T39: =H63 -> 0
E40: =C40*D40 -> 0 | F40: =IF($N40=TRUE,$E40/F$13,$E40*(1+(1/F$13))) -> 0 | G40: =IF($N40=TRUE,$E40/G$13,$E40*(1+(1/G$13))) -> 0 | H40: =IF($N40=TRUE,$E40/H$13,$E40*(1+(1/H$13))) -> 0 | I40: =IF($N40=TRUE,$E40/I$13,$E40*(1+(1/I$13))) -> 0 | J40: =IF($N40=TRUE,$E40/J$13,$E40*(1+(1/J$13))) -> 0 | K40: =IF($N40=TRUE,$E40/K$13,$E40*(1+(1/K$13))) -> 0 | L40: =IF($N40=TRUE,$E40/L$13,$E40*(1+(1/L$13))) -> 0 | M40: =IF($N40=TRUE,$E40/M$13,$E40*(1+(1/M$13))) -> 0 | N40: FALSE | S40: =G13 -> 25 | T40: =G63 -> 0
E41: =C41*D41 -> 0 | F41: =IF($N41=TRUE,$E41/F$13,$E41*(1+(1/F$13))) -> 0 | G41: =IF($N41=TRUE,$E41/G$13,$E41*(1+(1/G$13))) -> 0 | H41: =IF($N41=TRUE,$E41/H$13,$E41*(1+(1/H$13))) -> 0 | I41: =IF($N41=TRUE,$E41/I$13,$E41*(1+(1/I$13))) -> 0 | J41: =IF($N41=TRUE,$E41/J$13,$E41*(1+(1/J$13))) -> 0 | K41: =IF($N41=TRUE,$E41/K$13,$E41*(1+(1/K$13))) -> 0 | L41: =IF($N41=TRUE,$E41/L$13,$E41*(1+(1/L$13))) -> 0 | M41: =IF($N41=TRUE,$E41/M$13,$E41*(1+(1/M$13))) -> 0 | N41: FALSE | S41: =F13 -> 10 | T41: =F63 -> 0
E42: =C42*D42 -> 0 | F42: =IF($N42=TRUE,$E42/F$13,$E42*(1+(1/F$13))) -> 0 | G42: =IF($N42=TRUE,$E42/G$13,$E42*(1+(1/G$13))) -> 0 | H42: =IF($N42=TRUE,$E42/H$13,$E42*(1+(1/H$13))) -> 0 | I42: =IF($N42=TRUE,$E42/I$13,$E42*(1+(1/I$13))) -> 0 | J42: =IF($N42=TRUE,$E42/J$13,$E42*(1+(1/J$13))) -> 0 | K42: =IF($N42=TRUE,$E42/K$13,$E42*(1+(1/K$13))) -> 0 | L42: =IF($N42=TRUE,$E42/L$13,$E42*(1+(1/L$13))) -> 0 | M42: =IF($N42=TRUE,$E42/M$13,$E42*(1+(1/M$13))) -> 0 | N42: FALSE
